Workbook

Sheet ReadMe
B1: DECISION MAKING USING FINANCIAL STATEMENTS - Group project: Excel workings
B2: Industry: Indian listed logistics & freight-transport services | 10 companies | 7 financial years, FY2020-FY2026
B4: 1. Purpose
B5: Ratio analysis (liquidity, leverage, activity, profitability and valuation), DuPont analysis, industry comparison and statistical analysis of 10 listed Indian logistics companies over FY2020-FY2026. The 10 firms are treated as the whole industry, so every industry benchmark in this workbook is computed from these 10 firms only.
B7: 2. Sheet map (click a sheet name to open it)
B8: Setup | C8: Settings used by the formulas (days in the year) and the textbook benchmark norms.
B9: Sources | C9: Links to the annual reports / financial statements of every company.
B10: Firm_Profiles | C10: The 10 firms, their segments and business models, and the evidence that they form one industry.
B11: Scorecard | C11: Key ratios as 7-year averages (FY2020-FY2026) for every firm vs the industry aggregate and the 10-firm median, with a composite ranking.
B12: Industry_Compare | C12: Every ratio for every firm and year, with industry aggregate, mean, median, standard deviation, minimum, maximum, assessment against the median and rank.
B13: Statistics | C13: Descriptive statistics, correlation matrix (with caution notes), paired t-tests FY2020 vs FY2026, growth and stability.
B14: Panel | C14: 70 firm-year observations of the key variables (linked to the company sheets); the data used by Statistics.
B15: Industry | C15: The 10 firms added together line by line, with the same ratio formulas (size-weighted industry ratios).
B16: Tiger ... MahindraLog | C16: One sheet per company: P&L, balance sheet, cash flow statement, market data, working figures, all ratios and the DuPont analysis.
B18: 3. Conventions
B19: Blue figures on a light-blue background are inputs taken from the annual reports; black cells are formulas; green cells are links to another sheet; a yellow background marks an adjusted input, explained in the cell comment on the row label.
B20: Liquidity and capital-structure (leverage) ratios are shown in ratio form, e.g. 1.65:1. Coverage, turnover and valuation ratios are shown as plain numbers, days as whole numbers, and margins / returns as percentages.
B21: N/M = not meaningful. It is used only where a ratio cannot be interpreted: the denominator is nil or negative (negative net worth, no inventory held, no dividend declared, loss-making EPS for P/E, a net cash inflow from investing for the capital expenditure ratio). N/C = not comparable (Allcargo valuation ratios, see section 6). n.a. = not applicable (per-share data for the industry aggregate).
B22: All amounts are in Rs crore; per-share data in Rs. FY2026 = April 2025 - March 2026. Percentages are stored as fractions.
B24: 4. Data and sources
B25: Consolidated statement of profit and loss, balance sheet and cash flow statement for FY2020-FY2026, and the year-end share price, for each company, taken from the companies' annual reports. The links are on the Sources sheet and in row 3 of each company sheet. The figures were collected with the Screener.in Excel export (ALL_10_Companies.xlsx), which condenses each statement into a standard set of line items. No FY2019 figures are used anywhere in the workbook.
B27: 5. Basis of calculation
B28: - Closing balances: every ratio that uses a balance-sheet figure uses the closing (31 March) balance of the same year. No opening or average balances are used, so the analysis needs no FY2019 data.
B29: - EBIT = operating profit = Operating EBITDA - depreciation, i.e. before other income and exceptional items. This EBIT is used for the operating profit margin, interest coverage, earning power, ROCE and the five-step DuPont, so that treasury income and one-off gains or losses do not distort operating performance. PBT = EBIT + other income - finance costs, which agrees with the reported PBT for every firm-year.
B30: - Current assets and current liabilities: the condensed statements show "other assets" (all assets other than fixed assets, CWIP and investments) and "other liabilities" (all liabilities other than borrowings and equity), which are used as proxies. Trade payables are not shown separately, so creditor days and the cash conversion cycle are indicative only.
B31: - Debt = total borrowings including lease liabilities (long-term and short-term borrowings are not separated in the data).
... B48: 9. Review of N/M results (live counts)
B49: Sheet | C49: N/M cells | D49: N/C cells | E49: Where N/M remains and why
B50: Tiger | C50: =COUNTIF(Tiger!$D$94:$J$177,"N/M") -> 23 | D50: =COUNTIF(Tiger!$D$94:$J$177,"N/C") -> 0 | E50: Inventory turnover - no inventory held (all years); inventory days shown as 0; dividend coverage - no dividend declared (FY20-21, FY23-26); capital expenditure ratio - net cash inflow from investing (FY20, FY23, FY25-26); debt/EBITDA and EV/EBITDA - negative operating EBITDA (FY20-21); P/E - loss year (FY20-21).
B51: Allcargo | C51: =COUNTIF(Allcargo!$D$94:$J$177,"N/M") -> 6 | D51: =COUNTIF(Allcargo!$D$94:$J$177,"N/C") -> 30 | E51: Inventory turnover - no inventory held (FY25-26); inventory days shown as 0; dividend coverage - no dividend declared (FY26); capital expenditure ratio - net cash inflow from investing (FY21, FY25-26); N/C: P/E, P/B, EV/EBITDA, earnings and dividend yield (FY20-25) - demerger-adjusted prices.
B52: BlueDart | C52: =COUNTIF(BlueDart!$D$94:$J$177,"N/M") -> 4 | D52: =COUNTIF(BlueDart!$D$94:$J$177,"N/C") -> 0 | E52: Dividend coverage - no dividend declared (FY20); capital expenditure ratio - net cash inflow from investing (FY22); P/E - loss year (FY20); working capital turnover - negative net working capital (FY20).
B53: CONCOR | C53: =COUNTIF(CONCOR!$D$94:$J$177,"N/M") -> 1 | D53: =COUNTIF(CONCOR!$D$94:$J$177,"N/C") -> 0 | E53: Capital expenditure ratio - net cash inflow from investing (FY21).
B54: JetFreight | C54: =COUNTIF(JetFreight!$D$94:$J$177,"N/M") -> 17 | D54: =COUNTIF(JetFreight!$D$94:$J$177,"N/C") -> 0 | E54: Inventory turnover - no inventory held (all years); inventory days shown as 0; dividend coverage - no dividend declared (FY20-21, FY23-26); capital expenditure ratio - net cash inflow from investing (FY26); debt/EBITDA and EV/EBITDA - negative operating EBITDA (FY20); P/E - loss year (FY20).
B55: Patel | C55: =COUNTIF(Patel!$D$94:$J$177,"N/M") -> 12 | D55: =COUNTIF(Patel!$D$94:$J$177,"N/C") -> 0 | E55: Inventory turnover - no inventory held (all years); inventory days shown as 0; capital expenditure ratio - net cash inflow from investing (FY20-21, FY23-25).
B56: Sical | C56: =COUNTIF(Sical!$D$94:$J$177,"N/M") -> 57 | D56: =COUNTIF(Sical!$D$94:$J$177,"N/C") -> 0 | E56: Debt-equity, gearing, ROE, P/B and equity multiplier - negative net worth (FY21-22, FY25); dividend coverage - no dividend declared (all years); capital expenditure ratio - net cash inflow from investing (FY23, FY26); debt/EBITDA and EV/EBITDA - negative operating EBITDA (FY20-22); P/E - loss year (FY20-25); working capital turnover - negative net working capital (FY20-25).
B57: TCI | C57: =COUNTIF(TCI!$D$94:$J$177,"N/M") -> 0 | D57: =COUNTIF(TCI!$D$94:$J$177,"N/C") -> 0 | E57: None.
B58: Shreeji | C58: =COUNTIF(Shreeji!$D$94:$J$177,"N/M") -> 7 | D58: =COUNTIF(Shreeji!$D$94:$J$177,"N/C") -> 0 | E58: Dividend coverage - no dividend declared (FY25-26); capital expenditure ratio - net cash inflow from investing (FY24, FY26); P/E - loss year (FY21); payout and retention - dividend paid in a loss year (FY21).
B59: MahindraLog | C59: =COUNTIF(MahindraLog!$D$94:$J$177,"N/M") -> 12 | D59: =COUNTIF(MahindraLog!$D$94:$J$177,"N/C") -> 0 | E59: Inventory turnover - no inventory held (FY20-21, FY24-26); inventory days shown as 0; capital expenditure ratio - net cash inflow from investing (FY20); P/E - loss year (FY24-25); payout and retention - dividend paid in a loss year (FY24-25).
B60: Industry | C60: =COUNTIF(Industry!$D$95:$J$178,"N/M") -> 3 | D60: =COUNTIF(Industry!$D$95:$J$178,"N/C") -> 0 | E60: P/E - loss year (FY21); payout and retention - dividend paid in a loss year (FY21).
B62: Counts cover the ratio and DuPont sections (FY2020-FY2026 columns). All earlier N/M cells were reviewed: N/M now appears only where the ratio is genuinely not meaningful; where a value can be calculated it is shown (e.g. inventory days of 0 when no inventory is held, and a 0% payout ratio when no dividend is paid).
...

Sheet Setup
A1: Setup - model settings and benchmark norms
A2: Settings referenced by the formulas, and the textbook norms quoted in the "Norm / unit" column of the company sheets.
B4: 1. GENERAL SETTINGS
B5: Industry | C5: Indian listed logistics & freight-transport services
B6: Currency & scale | C6: Rs crore (per-share data in Rs)
B7: Financial statements | C7: Consolidated where published (standalone otherwise)
B8: Days in a financial year | C8: 365
B9: Analysis period | C9: FY2020-FY2026 (7 years; FY = April to March)
B10: Balance-sheet basis for ratios | C10: Closing balance of the same year (no averages, no FY2019 figures)
B11: Maximum corporate tax rate (cap on t) | C11: 0.34944
B13: 2. TEXTBOOK BENCHMARK NORMS (reference only)
B14: Ratio | C14: Norm | D14: Shown as | E14: Rationale
B15: Current ratio | C15: 2 : 1 | D15: ratio | E15: Current assets twice current liabilities give creditors a 100% margin of safety.
B16: Quick (acid-test) ratio | C16: 1 : 1 | D16: ratio | E16: Stricter test that leaves out inventory and prepaid expenses.
B17: Cash ratio | C17: 0.5 : 1 | D17: ratio | E17: Ability to meet current obligations from cash and near-cash assets alone.
B18: Debt to capital employed | C18: max 0.5 : 1 | D18: ratio | E18: Debt should not exceed half of permanent capital.
B19: Debt to total assets | C19: max 0.5 : 1 | D19: ratio | E19: Total debt should not exceed half of the asset base.
B20: Proprietary ratio | C20: min 0.5 : 1 | D20: ratio | E20: Owners' funds should finance at least half of total assets.
B21: Interest coverage | C21: above 3 | D21: number | E21: Adequate cushion for finance costs out of operating profit.
B22: Debt-service coverage ratio | C22: above 1.25 | D22: number | E22: Below 1 means earnings do not cover interest plus principal.
B23: Capital expenditure ratio | C23: above 1 | D23: number | E23: Operating cash flow fully funds net capital expenditure.
B25: Liquidity and capital-structure ratios are shown in ratio form (e.g. 1.65:1). Coverage, turnover and valuation ratios are shown as plain numbers; margins and returns as percentages.

Sheet Sources
A1: Sources - annual reports and financial statements
A2: Primary sources for every company sheet. Figures are the consolidated statements in these reports, compiled into one data sheet per company through the Screener.in Excel export (ALL_10_Companies.xlsx); the export was used only to collect the numbers.
A4: # | B4: Company | C4: BSE code | D4: Document | E4: Period | F4: Link
A5: 1 | B5: Tiger Logistics (India) Ltd | C5: 536264 | D5: Annual reports - company investor page | E5: FY2020-FY2026 | F5: https://www.tigerlogistics.in/Annual_Report.php
A6: 2 | B6: Tiger Logistics (India) Ltd | C6: 536264 | D6: Annual reports - BSE corporate filings | E6: FY2020-FY2026 | F6: https://www.bseindia.com/stock-share-price/tiger-logistics-india-ltd/tigerlogs/536264/financials-annual-reports/
A7: 3 | B7: Allcargo Logistics Ltd | C7: 532749 | D7: Annual reports - company investor page | E7: FY2020-FY2026 | F7: https://www.allcargologistics.com/investor/logistics-annual-reports
A8: 4 | B8: Allcargo Logistics Ltd | C8: 532749 | D8: Annual reports - BSE corporate filings | E8: FY2020-FY2026 | F8: https://www.bseindia.com/stock-share-price/allcargo-logistics-ltd/allcargo/532749/financials-annual-reports/
A9: 5 | B9: Allcargo Logistics Ltd | C9: 532749 | D9: Annual Report 2022-23 | E9: FY2023 | F9: https://www.allcargologistics.com/cms/annual-reports/February2025/8QxMvclnT0owjBnY34Zk.pdf
A10: 6 | B10: Allcargo Logistics Ltd | C10: 532749 | D10: Annual Report 2023-24 | E10: FY2024 | F10: https://www.allcargologistics.com/cms/annual-reports/February2025/Bsl5vDz8atYU5wg09BlM.pdf
A11: 7 | B11: Blue Dart Express Ltd | C11: 526612 | D11: Annual reports - company investor page | E11: FY2020-FY2026 | F11: https://www.bluedart.com/financials
A12: 8 | B12: Blue Dart Express Ltd | C12: 526612 | D12: Annual reports - BSE corporate filings | E12: FY2020-FY2026 | F12: https://www.bseindia.com/stock-share-price/blue-dart-express-ltd/bluedart/526612/financials-annual-reports/
A13: 9 | B13: Blue Dart Express Ltd | C13: 526612 | D13: Annual Report 2019-20 | E13: FY2020 | F13: https://api.bluedart.com/documents/20182/0/Blue+Dart+Annual+Report-2019-2020.pdf/995ddbb8-b493-399f-2cc7-b5444cacf917
A14: 10 | B14: Blue Dart Express Ltd | C14: 526612 | D14: Annual Report 2024-25 | E14: FY2025 | F14: https://www.bluedart.com/documents/d/guest/annual-report-2024-25
A15: 11 | B15: Container Corporation of India Ltd | C15: 531344 | D15: Annual reports - company investor page | E15: FY2020-FY2026 | F15: https://www.concorindia.co.in/annual_report.aspx
A16: 12 | B16: Container Corporation of India Ltd | C16: 531344 | D16: Annual reports - BSE corporate filings | E16: FY2020-FY2026 | F16: https://www.bseindia.com/stock-share-price/container-corporation-of-india-ltd/concor/531344/financials-annual-reports/
... A46: 42 | B46: Mahindra Logistics Ltd | C46: 540768 | D46: Audited financial results FY2024-25 | E46: FY2025 | F46: https://mahindralogistics.com/tabs/cms/files/Annual-Financial-Results-FY-2025.pdf
B48: Notes
B49: - Where a single-year PDF is not listed, that year's report is available from the company's annual-report page and from the BSE annual-report page given for the company.
B50: - Share prices are the closing prices on the last trading day of March (BSE/NSE), adjusted for splits and bonus issues.
B51: - Company-specific adjustments to the data are explained in cell comments on the company sheets (yellow cells) and in the ReadMe.

Sheet Firm_Profiles
A1: Firm selection - the 10 listed Indian logistics companies and evidence that they form one industry
A2: Columns H-Q are linked to the company sheets. A cost structure dominated by direct operating (freight / handling) costs, negligible inventory and receivable-led working capital show a common operating model; asset intensity separates the asset-light forwarders / 3PLs from the asset-heavy network operators.
A4: # | B4: Company | C4: NSE symbol | D4: BSE code | E4: Segment / value proposition | F4: Business model | G4: Asset group (vs median net block / TA) | H4: Sales FY2026 (Rs cr) | I4: Total assets FY2026 (Rs cr) | J4: Market cap FY2026 (Rs cr) | K4: Sales CAGR FY20-26 | L4: Direct operating cost % sales (7-yr avg) | M4: Employee cost % sales (7-yr avg) | N4: Inventory % total assets (FY20-26) | O4: Receivables % total assets (FY20-26) | P4: Net block % total assets (FY20-26) | Q4: Operating EBITDA margin (7-yr avg)
A5: 1 | B5: Tiger Logistics (India) Ltd | C5: TIGERLOGS | D5: 536264 | E5: International freight forwarding (sea & air), customs brokerage, project cargo | F5: Asset-light forwarder | G5: =IF(P5>=MEDIAN($P$5:$P$14),"Asset-heavy","Asset-light") -> Asset-light | H5: =Tiger!J7 -> 572.82 | I5: =Tiger!J49 -> 262.62 | J5: =Tiger!J82 -> 252.623 | K5: =(Tiger!J7/Tiger!D7)^(1/6)-1 -> 0.11290974 | L5: =Tiger!K135 -> 0.90008469 | M5: =Tiger!K137 -> 0.042590791 | N5: =SUM(Tiger!D51:J51)/SUM(Tiger!D49:J49) -> 0 | O5: =SUM(Tiger!D50:J50)/SUM(Tiger!D49:J49) -> 0.54298621 | P5: =SUM(Tiger!D45:J45)/SUM(Tiger!D49:J49) -> 0.059499229 | Q5: =Tiger!K130 -> 0.029629489
A6: 2 | B6: Allcargo Logistics Ltd | C6: ALLCARGO | D6: 532749 | E6: LCL consolidation/NVOCC (international business demerged to Allcargo Global w.e.f. 1-Nov-2025); domestic express & contract logistics | F6: Asset-light network operator | G6: =IF(P6>=MEDIAN($P$5:$P$14),"Asset-heavy","Asset-light") -> Asset-heavy | H6: =Allcargo!J7 -> 2058 | I6: =Allcargo!J49 -> 1736 | J6: =Allcargo!J82 -> 1075.4204 | K6: =(Allcargo!J7/Allcargo!D7)^(1/6)-1 -> -0.19109651 | L6: =Allcargo!K135 -> 0.76369076 | M6: =Allcargo!K137 -> 0.11942794 | N6: =SUM(Allcargo!D51:J51)/SUM(Allcargo!D49:J49) -> 0.00078673889 | O6: =SUM(Allcargo!D50:J50)/SUM(Allcargo!D49:J49) -> 0.28615394 | P6: =SUM(Allcargo!D45:J45)/SUM(Allcargo!D49:J49) -> 0.37746854 | Q6: =Allcargo!K130 -> 0.073607981
A7: 3 | B7: Blue Dart Express Ltd | C7: BLUEDART | D7: 526612 | E7: Express air & ground courier and integrated transport (DHL Group); dedicated freighter fleet | F7: Asset-heavy express network | G7: =IF(P7>=MEDIAN($P$5:$P$14),"Asset-heavy","Asset-light") -> Asset-heavy | H7: =BlueDart!J7 -> 6140.88 | I7: =BlueDart!J49 -> 4126.85 | J7: =BlueDart!J82 -> 11250.39 | K7: =(BlueDart!J7/BlueDart!D7)^(1/6)-1 -> 0.11620728 | L7: =BlueDart!K135 -> 0.57413445 | M7: =BlueDart!K137 -> 0.18587756 | N7: =SUM(BlueDart!D51:J51)/SUM(BlueDart!D49:J49) -> 0.012802242 | O7: =SUM(BlueDart!D50:J50)/SUM(BlueDart!D49:J49) -> 0.20304214 | P7: =SUM(BlueDart!D45:J45)/SUM(BlueDart!D49:J49) -> 0.51634353 | Q7: =BlueDart!K130 -> 0.17658992
A8: 4 | B8: Container Corporation of India Ltd | C8: CONCOR | D8: 531344 | E8: Rail-based EXIM & domestic container logistics, ICDs/CFSs (Navratna CPSE, Ministry of Railways) | F8: Asset-heavy multimodal | G8: =IF(P8>=MEDIAN($P$5:$P$14),"Asset-heavy","Asset-light") -> Asset-heavy | H8: =CONCOR!J7 -> 9078.97 | I8: =CONCOR!J49 -> 15175.78 | J8: =CONCOR!J82 -> 32390.848 | K8: =(CONCOR!J7/CONCOR!D7)^(1/6)-1 -> 0.056454767 | L8: =CONCOR!K135 -> 0.65386661 | M8: =CONCOR!K137 -> 0.05554146 | N8: =SUM(CONCOR!D51:J51)/SUM(CONCOR!D49:J49) -> 0.0028825407 | O8: =SUM(CONCOR!D50:J50)/SUM(CONCOR!D49:J49) -> 0.020580932 | P8: =SUM(CONCOR!D45:J45)/SUM(CONCOR!D49:J49) -> 0.44638229 | Q8: =CONCOR!K130 -> 0.21971019
A9: 5 | B9: Jet Freight Logistics Ltd | C9: JETFREIGHT | D9: 543420 | E9: International air & ocean freight forwarding (incl. perishables), customs clearance | F9: Asset-light forwarder | G9: =IF(P9>=MEDIAN($P$5:$P$14),"Asset-heavy","Asset-light") -> Asset-light | H9: =JetFreight!J7 -> 444.08 | I9: =JetFreight!J49 -> 194.09 | J9: =JetFreight!J82 -> 79.1584 | K9: =(JetFreight!J7/JetFreight!D7)^(1/6)-1 -> 0.067684882 | L9: =JetFreight!K135 -> 0.924891 | M9: =JetFreight!K137 -> 0.040392871 | N9: =SUM(JetFreight!D51:J51)/SUM(JetFreight!D49:J49) -> 0 | O9: =SUM(JetFreight!D50:J50)/SUM(JetFreight!D49:J49) -> 0.42369073 | P9: =SUM(JetFreight!D45:J45)/SUM(JetFreight!D49:J49) -> 0.183062 | Q9: =JetFreight!K130 -> 0.020453399
A10: 6 | B10: Patel Integrated Logistics Ltd | C10: PATINTLOG | D10: 526381 | E10: Surface transport (Patel Roadways), domestic & international air-freight consolidation | F10: Asset-light carrier/consolidator | G10: =IF(P10>=MEDIAN($P$5:$P$14),"Asset-heavy","Asset-light") -> Asset-light | H10: =Patel!J7 -> 357.14 | I10: =Patel!J49 -> 163.32 | J10: =Patel!J82 -> 57.4896 | K10: =(Patel!J7/Patel!D7)^(1/6)-1 -> 0.0046143172 | L10: =Patel!K135 -> 0.90083674 | M10: =Patel!K137 -> 0.046566838 | N10: =SUM(Patel!D51:J51)/SUM(Patel!D49:J49) -> 0 | O10: =SUM(Patel!D50:J50)/SUM(Patel!D49:J49) -> 0.41704385 | P10: =SUM(Patel!D45:J45)/SUM(Patel!D49:J49) -> 0.28157151 | Q10: =Patel!K130 -> 0.0290875
A11: 7 | B11: Sical Logistics Ltd | C11: SICALLOG | D11: 520086 | E11: Bulk/mining logistics (coal), port & rail-road handling; IBC resolution plan of Pristine Malwa Logistics Park approved by NCLT Chennai (8-Dec-2022) | F11: Asset-heavy bulk logistics | G11: =IF(P11>=MEDIAN($P$5:$P$14),"Asset-heavy","Asset-light") -> Asset-heavy | H11: =Sical!J7 -> 385.68 | I11: =Sical!J49 -> 906.73 | J11: =Sical!J82 -> 502.69378 | K11: =(Sical!J7/Sical!D7)^(1/6)-1 -> -0.14765313 | L11: =Sical!K135 -> 0.77007687 | M11: =Sical!K137 -> 0.094975198 | N11: =SUM(Sical!D51:J51)/SUM(Sical!D49:J49) -> 0.0049394181 | O11: =SUM(Sical!D50:J50)/SUM(Sical!D49:J49) -> 0.091790321 | P11: =SUM(Sical!D45:J45)/SUM(Sical!D49:J49) -> 0.51796157 | Q11: =Sical!K130 -> 0.041720612
A12: 8 | B12: Transport Corporation of India Ltd | C12: TCI | D12: 532349 | E12: Integrated multimodal: road freight, supply-chain solutions/warehousing, coastal seaways, rail (JV with CONCOR) | F12: Hybrid multimodal | G12: =IF(P12>=MEDIAN($P$5:$P$14),"Asset-heavy","Asset-light") -> Asset-heavy | H12: =TCI!J7 -> 4916.77 | I12: =TCI!J49 -> 3481.86 | J12: =TCI!J82 -> 7079.41 | K12: =(TCI!J7/TCI!D7)^(1/6)-1 -> 0.10384815 | L12: =TCI!K135 -> 0.8143326 | M12: =TCI!K137 -> 0.054711809 | N12: =SUM(TCI!D51:J51)/SUM(TCI!D49:J49) -> 0.0036293535 | O12: =SUM(TCI!D50:J50)/SUM(TCI!D49:J49) -> 0.25858037 | P12: =SUM(TCI!D45:J45)/SUM(TCI!D49:J49) -> 0.38034014 | Q12: =TCI!K130 -> 0.10460636
A13: 9 | B13: Shreeji Translogistics Ltd | C13: — (BSE only) | D13: 540738 | E13: Road freight transport (full & part truck-load) and allied logistics | F13: Asset-light road carrier | G13: =IF(P13>=MEDIAN($P$5:$P$14),"Asset-heavy","Asset-light") -> Asset-light | H13: =Shreeji!J7 -> 234.29 | I13: =Shreeji!J49 -> 119.52 | J13: =Shreeji!J82 -> 41.1012 | K13: =(Shreeji!J7/Shreeji!D7)^(1/6)-1 -> 0.13429716 | L13: =Shreeji!K135 -> 0.80428674 | M13: =Shreeji!K137 -> 0.059367831 | N13: =SUM(Shreeji!D51:J51)/SUM(Shreeji!D49:J49) -> 0.021844079 | O13: =SUM(Shreeji!D50:J50)/SUM(Shreeji!D49:J49) -> 0.51219581 | P13: =SUM(Shreeji!D45:J45)/SUM(Shreeji!D49:J49) -> 0.25174176 | Q13: =Shreeji!K130 -> 0.072103023
A14: 10 | B14: Mahindra Logistics Ltd | C14: MAHLOG | D14: 540768 | E14: Integrated 3PL: contract logistics & warehousing, B2B express, freight forwarding, last-mile, enterprise mobility | F14: Asset-light 3PL (leased) | G14: =IF(P14>=MEDIAN($P$5:$P$14),"Asset-heavy","Asset-light") -> Asset-light | H14: =MahindraLog!J7 -> 6999.3 | I14: =MahindraLog!J49 -> 3105.01 | J14: =MahindraLog!J82 -> 3301.376 | K14: =(MahindraLog!J7/MahindraLog!D7)^(1/6)-1 -> 0.12399336 | L14: =MahindraLog!K135 -> 0.85615338 | M14: =MahindraLog!K137 -> 0.07499944 | N14: =SUM(MahindraLog!D51:J51)/SUM(MahindraLog!D49:J49) -> 0.00011646926 | O14: =SUM(MahindraLog!D50:J50)/SUM(MahindraLog!D49:J49) -> 0.26453777 | P14: =SUM(MahindraLog!D45:J45)/SUM(MahindraLog!D49:J49) -> 0.3060559 | Q14: =MahindraLog!K130 -> 0.046407247
B15: Median | H15: =MEDIAN(H5:H14) -> 1315.41 | I15: =MEDIAN(I5:I14) -> 1321.365 | J15: =MEDIAN(J5:J14) -> 789.05709 | K15: =MEDIAN(K5:K14) -> 0.085766516 | L15: =MEDIAN(L5:L14) -> 0.80930967 | M15: =MEDIAN(M5:M14) -> 0.057454646 | N15: =MEDIAN(N5:N14) -> 0.0018346398 | O15: =MEDIAN(O5:O14) -> 0.27534586 | ... Q15: =MEDIAN(Q5:Q14) -> 0.059255135
B16: Mean | H16: =AVERAGE(H5:H14) -> 3118.793 | I16: =AVERAGE(I5:I14) -> 2927.178 | J16: =AVERAGE(J5:J14) -> 5603.051 | K16: =AVERAGE(K5:K14) -> 0.038126002 | L16: =AVERAGE(L5:L14) -> 0.79623538 | M16: =AVERAGE(M5:M14) -> 0.077445173 | N16: =AVERAGE(N5:N14) -> 0.0047000842 | O16: =AVERAGE(O5:O14) -> 0.30206021 | ... Q16: =AVERAGE(Q5:Q14) -> 0.081391573
B17: Minimum | H17: =MIN(H5:H14) -> 234.29 | I17: =MIN(I5:I14) -> 119.52 | J17: =MIN(J5:J14) -> 41.1012 | K17: =MIN(K5:K14) -> -0.19109651 | L17: =MIN(L5:L14) -> 0.57413445 | M17: =MIN(M5:M14) -> 0.040392871 | N17: =MIN(N5:N14) -> 0 | O17: =MIN(O5:O14) -> 0.020580932 | ... Q17: =MIN(Q5:Q14) -> 0.020453399
B18: Maximum | H18: =MAX(H5:H14) -> 9078.97 | I18: =MAX(I5:I14) -> 15175.78 | J18: =MAX(J5:J14) -> 32390.848 | K18: =MAX(K5:K14) -> 0.13429716 | L18: =MAX(L5:L14) -> 0.924891 | M18: =MAX(M5:M14) -> 0.18587756 | N18: =MAX(N5:N14) -> 0.021844079 | O18: =MAX(O5:O14) -> 0.54298621 | ... Q18: =MAX(Q5:Q14) -> 0.21971019
B19: Coeff. of variation (SD / mean) | H19: =IF(ABS(AVERAGE(H5:H14))>0,STDEV(H5:H14)/ABS(AVERAGE(H5:H14)),"N/M") -> 1.0747906 | I19: =IF(ABS(AVERAGE(I5:I14))>0,STDEV(I5:I14)/ABS(AVERAGE(I5:I14)),"N/M") -> 1.5588836 | J19: =IF(ABS(AVERAGE(J5:J14))>0,STDEV(J5:J14)/ABS(AVERAGE(J5:J14)),"N/M") -> 1.8086734 | K19: =IF(ABS(AVERAGE(K5:K14))>0,STDEV(K5:K14)/ABS(AVERAGE(K5:K14)),"N/M") -> 3.0540321 | L19: =IF(ABS(AVERAGE(L5:L14))>0,STDEV(L5:L14)/ABS(AVERAGE(L5:L14)),"N/M") -> 0.14110106 | M19: =IF(ABS(AVERAGE(M5:M14))>0,STDEV(M5:M14)/ABS(AVERAGE(M5:M14)),"N/M") -> 0.58854746 | N19: =IF(ABS(AVERAGE(N5:N14))>0,STDEV(N5:N14)/ABS(AVERAGE(N5:N14)),"N/M") -> 1.5320597 | O19: =IF(ABS(AVERAGE(O5:O14))>0,STDEV(O5:O14)/ABS(AVERAGE(O5:O14)),"N/M") -> 0.57023666 | ... Q19: =IF(ABS(AVERAGE(Q5:Q14))>0,STDEV(Q5:Q14)/ABS(AVERAGE(Q5:Q14)),"N/M") -> 0.82730417
B21: Reading: direct operating (freight / handling) costs are the largest cost for every firm and inventory is negligible for all ten (about 2% of total assets at most), which supports treating the 10 firms as one industry; the wide spread of net block / total assets reflects different value propositions (asset-light vs asset-heavy). Allcargo's CAGR is negative because FY2026 is after the demerger of its international business.

Sheet Scorecard
A1: Scorecard - key ratios, 7-year average FY2020-FY2026
A2: Each figure is the average of the seven yearly ratios (FY2020-FY2026) from the company sheets. Green = better than the 10-firm median, red = weaker (direction shown in column B). Valuation ratios have no normative direction and are not coloured.
A4: A. Key ratios - 7-year average (FY2020-FY2026)
A5: Ratio | B5: Category / direction | C5: Tiger | D5: Allcargo | E5: Blue Dart | F5: CONCOR | G5: Jet Freight | H5: Patel | I5: Sical | J5: TCI | K5: Shreeji | L5: Mahindra Log. | M5: Industry (agg.) | N5: Median (10 firms)
A6: Current ratio | B6: Liquidity (↑) | C6: =Tiger!K95 -> 4.8832317 | D6: =Allcargo!K95 -> 1.6559883 | E6: =BlueDart!K95 -> 1.2083102 | F6: =CONCOR!K95 -> 3.9096987 | G6: =JetFreight!K95 -> 2.7399296 | H6: =Patel!K95 -> 5.5817034 | I6: =Sical!K95 -> 0.7195622 | J6: =TCI!K95 -> 2.8768546 | K6: =Shreeji!K95 -> 5.0975533 | L6: =MahindraLog!K95 -> 1.4129884 | M6: =Industry!K96 -> 1.9742087 | N6: =IF(COUNT(C6:L6)=0,"N/M",MEDIAN(C6:L6)) -> 2.8083921
A7: Quick (acid-test) ratio | B7: Liquidity (↑) | C7: =Tiger!K96 -> 4.1690597 | D7: =Allcargo!K96 -> 1.0636674 | E7: =BlueDart!K96 -> 0.82047016 | F7: =CONCOR!K96 -> 2.3952545 | G7: =JetFreight!K96 -> 1.620697 | H7: =Patel!K96 -> 4.3914109 | I7: =Sical!K96 -> 0.46681949 | J7: =TCI!K96 -> 1.9838517 | K7: =Shreeji!K96 -> 3.8810091 | L7: =MahindraLog!K96 -> 0.69863375 | M7: =Industry!K97 -> 1.2448907 | N7: =IF(COUNT(C7:L7)=0,"N/M",MEDIAN(C7:L7)) -> 1.8022743
A8: Cash flow from operations ratio | B8: Liquidity (↑) | C8: =Tiger!K99 -> 0.12295018 | D8: =Allcargo!K99 -> 0.33150185 | E8: =BlueDart!K99 -> 0.72776984 | F8: =CONCOR!K99 -> 1.2513667 | G8: =JetFreight!K99 -> -0.11414869 | H8: =Patel!K99 -> 0.10835287 | I8: =Sical!K99 -> 0.12059511 | J8: =TCI!K99 -> 0.99039578 | K8: =Shreeji!K99 -> 0.43081607 | L8: =MahindraLog!K99 -> 0.20161113 | M8: =Industry!K100 -> 0.55763214 | N8: =IF(COUNT(C8:L8)=0,"N/M",MEDIAN(C8:L8)) -> 0.26655649
A9: Debt-equity ratio | B9: Leverage (↓) | C9: =Tiger!K101 -> 0.24661787 | D9: =Allcargo!K101 -> 0.87612163 | E9: =BlueDart!K101 -> 1.1280755 | F9: =CONCOR!K101 -> 0.062736366 | G9: =JetFreight!K101 -> 1.3550845 | H9: =Patel!K101 -> 0.29634174 | I9: =Sical!K101 -> 8.2478837 | J9: =TCI!K101 -> 0.15977623 | K9: =Shreeji!K101 -> 1.2179689 | L9: =MahindraLog!K101 -> 1.0148062 | M9: =Industry!K102 -> 0.30963722 | N9: =IF(COUNT(C9:L9)=0,"N/M",MEDIAN(C9:L9)) -> 0.94546393
A10: Proprietary ratio | B10: Leverage (↑) | C10: =Tiger!K105 -> 0.64580193 | D10: =Allcargo!K105 -> 0.34869893 | E10: =BlueDart!K105 -> 0.33080972 | F10: =CONCOR!K105 -> 0.84060615 | G10: =JetFreight!K105 -> 0.30649204 | H10: =Patel!K105 -> 0.66174853 | I10: =Sical!K105 -> -0.079794883 | J10: =TCI!K105 -> 0.73518162 | K10: =Shreeji!K105 -> 0.4032542 | L10: =MahindraLog!K105 -> 0.28048555 | M10: =Industry!K106 -> 0.58700064 | N10: =IF(COUNT(C10:L10)=0,"N/M",MEDIAN(C10:L10)) -> 0.37597656
A11: Debt to EBITDA | B11: Leverage (↓) | C11: =Tiger!K107 -> 0.75113098 | D11: =Allcargo!K107 -> 2.8434977 | E11: =BlueDart!K107 -> 1.3147804 | F11: =CONCOR!K107 -> 0.42697979 | G11: =JetFreight!K107 -> 5.6555538 | H11: =Patel!K107 -> 4.7785377 | I11: =Sical!K107 -> 20.639178 | J11: =TCI!K107 -> 0.70349827 | K11: =Shreeji!K107 -> 4.1414082 | L11: =MahindraLog!K107 -> 2.3755368 | M11: =Industry!K108 -> 1.3775514 | N11: =IF(COUNT(C11:L11)=0,"N/M",MEDIAN(C11:L11)) -> 2.6095173
A12: Interest coverage ratio | B12: Coverage (↑) | C12: =Tiger!K109 -> 10.730958 | D12: =Allcargo!K109 -> 4.0494231 | E12: =BlueDart!K109 -> 4.777735 | F12: =CONCOR!K109 -> 18.439328 | G12: =JetFreight!K109 -> 1.1858265 | H12: =Patel!K109 -> 4.7808037 | I12: =Sical!K109 -> -1.4105085 | J12: =TCI!K109 -> 17.263744 | K12: =Shreeji!K109 -> 2.045678 | L12: =MahindraLog!K109 -> 1.7499748 | M12: =Industry!K110 -> 6.1443735 | N12: =IF(COUNT(C12:L12)=0,"N/M",MEDIAN(C12:L12)) -> 4.4135791
A13: Debt-service coverage ratio (DSCR) | B13: Coverage (↑) | C13: =Tiger!K114 -> 10.758914 | D13: =Allcargo!K114 -> 4.5920994 | E13: =BlueDart!K114 -> 2.3667539 | F13: =CONCOR!K114 -> 10.604068 | G13: =JetFreight!K114 -> 1.3424754 | H13: =Patel!K114 -> 3.3119867 | I13: =Sical!K114 -> -5.6077461 | J13: =TCI!K114 -> 16.090305 | K13: =Shreeji!K114 -> 3.0023597 | L13: =MahindraLog!K114 -> 2.7067417 | M13: =Industry!K115 -> 3.0150827 | N13: =IF(COUNT(C13:L13)=0,"N/M",MEDIAN(C13:L13)) -> 3.1571732
A14: Average collection period (days) | B14: Activity (↓) | C14: =Tiger!K119 -> 76.281334 | D14: =Allcargo!K119 -> 63.069257 | E14: =BlueDart!K119 -> 51.762184 | F14: =CONCOR!K119 -> 12.380379 | G14: =JetFreight!K119 -> 55.3619 | H14: =Patel!K119 -> 96.313471 | I14: =Sical!K119 -> 103.2761 | J14: =TCI!K119 -> 59.542759 | K14: =Shreeji!K119 -> 104.60979 | L14: =MahindraLog!K119 -> 45.718712 | M14: =Industry!K120 -> 46.139843 | N14: =IF(COUNT(C14:L14)=0,"N/M",MEDIAN(C14:L14)) -> 61.306008
A15: Fixed assets turnover (times) | B15: Activity (↑) | C15: =Tiger!K123 -> 47.430962 | D15: =Allcargo!K123 -> 4.3948625 | E15: =BlueDart!K123 -> 2.8163152 | F15: =CONCOR!K123 -> 1.3145974 | G15: =JetFreight!K123 -> 15.771494 | H15: =Patel!K123 -> 5.859202 | I15: =Sical!K123 -> 0.60484321 | J15: =TCI!K123 -> 4.1864023 | K15: =Shreeji!K123 -> 7.1944463 | L15: =MahindraLog!K123 -> 8.2546136 | M15: =Industry!K124 -> 2.7208254 | N15: =IF(COUNT(C15:L15)=0,"N/M",MEDIAN(C15:L15)) -> 5.1270322
A16: Total assets turnover (times) | B16: Activity (↑) | C16: =Tiger!K124 -> 2.8806467 | D16: =Allcargo!K124 -> 1.6321028 | E16: =BlueDart!K124 -> 1.4389931 | F16: =CONCOR!K124 -> 0.58508733 | G16: =JetFreight!K124 -> 2.9659525 | H16: =Patel!K124 -> 1.6385818 | I16: =Sical!K124 -> 0.33477339 | J16: =TCI!K124 -> 1.6231699 | K16: =Shreeji!K124 -> 1.7530154 | L16: =MahindraLog!K124 -> 2.1892969 | M16: =Industry!K125 -> 1.1428556 | N16: =IF(COUNT(C16:L16)=0,"N/M",MEDIAN(C16:L16)) -> 1.6353423
A17: Gross profit margin | B17: Profitability (↑) | C17: =Tiger!K129 -> 0.099915313 | D17: =Allcargo!K129 -> 0.23630924 | E17: =BlueDart!K129 -> 0.42586555 | F17: =CONCOR!K129 -> 0.34613339 | G17: =JetFreight!K129 -> 0.075109 | H17: =Patel!K129 -> 0.099163264 | I17: =Sical!K129 -> 0.22992313 | J17: =TCI!K129 -> 0.1856674 | K17: =Shreeji!K129 -> 0.19571326 | L17: =MahindraLog!K129 -> 0.14384662 | M17: =Industry!K130 -> 0.25888543 | N17: =IF(COUNT(C17:L17)=0,"N/M",MEDIAN(C17:L17)) -> 0.19069033
A18: Operating EBITDA margin | B18: Profitability (↑) | C18: =Tiger!K130 -> 0.029629489 | D18: =Allcargo!K130 -> 0.073607981 | E18: =BlueDart!K130 -> 0.17658992 | F18: =CONCOR!K130 -> 0.21971019 | G18: =JetFreight!K130 -> 0.020453399 | H18: =Patel!K130 -> 0.0290875 | I18: =Sical!K130 -> 0.041720612 | J18: =TCI!K130 -> 0.10460636 | K18: =Shreeji!K130 -> 0.072103023 | L18: =MahindraLog!K130 -> 0.046407247 | M18: =Industry!K131 -> 0.11740644 | N18: =IF(COUNT(C18:L18)=0,"N/M",MEDIAN(C18:L18)) -> 0.059255135
A19: Operating profit (EBIT) margin | B19: Profitability (↑) | C19: =Tiger!K131 -> 0.027035179 | D19: =Allcargo!K131 -> 0.02913258 | E19: =BlueDart!K131 -> 0.082258617 | F19: =CONCOR!K131 -> 0.14575848 | G19: =JetFreight!K131 -> 0.015028909 | H19: =Patel!K131 -> 0.019310825 | I19: =Sical!K131 -> -0.11299976 | J19: =TCI!K131 -> 0.073993461 | K19: =Shreeji!K131 -> 0.046968483 | L19: =MahindraLog!K131 -> 0.012903028 | M19: =Industry!K132 -> 0.067261761 | N19: =IF(COUNT(C19:L19)=0,"N/M",MEDIAN(C19:L19)) -> 0.02808388
A20: Net profit margin | B20: Profitability (↑) | C20: =Tiger!K133 -> 0.019312592 | D20: =Allcargo!K133 -> 0.025549208 | E20: =BlueDart!K133 -> 0.045375983 | F20: =CONCOR!K133 -> 0.12136961 | G20: =JetFreight!K133 -> 0.0013562643 | H20: =Patel!K133 -> 0.018081543 | I20: =Sical!K133 -> -0.77125135 | J20: =TCI!K133 -> 0.078488617 | K20: =Shreeji!K133 -> 0.027812603 | L20: =MahindraLog!K133 -> 0.0027070853 | M20: =Industry!K134 -> 0.044064558 | N20: =IF(COUNT(C20:L20)=0,"N/M",MEDIAN(C20:L20)) -> 0.0224309
A21: Operating ratio | B21: Expenses (↓) | C21: =Tiger!K140 -> 0.97037051 | D21: =Allcargo!K140 -> 0.92639202 | E21: =BlueDart!K140 -> 0.82341008 | F21: =CONCOR!K140 -> 0.78028981 | G21: =JetFreight!K140 -> 0.9795466 | H21: =Patel!K140 -> 0.9709125 | I21: =Sical!K140 -> 0.95827939 | J21: =TCI!K140 -> 0.89539364 | K21: =Shreeji!K140 -> 0.92789698 | L21: =MahindraLog!K140 -> 0.95359275 | M21: =Industry!K141 -> 0.88259356 | N21: =IF(COUNT(C21:L21)=0,"N/M",MEDIAN(C21:L21)) -> 0.94074487
A22: Return on assets (ROA) | B22: Returns (↑) | C22: =Tiger!K142 -> 0.073754177 | D22: =Allcargo!K142 -> 0.044572826 | E22: =BlueDart!K142 -> 0.069314504 | F22: =CONCOR!K142 -> 0.0720001 | G22: =JetFreight!K142 -> 0.0015715268 | H22: =Patel!K142 -> 0.032361336 | I22: =Sical!K142 -> -0.27701266 | J22: =TCI!K142 -> 0.12722538 | K22: =Shreeji!K142 -> 0.053066207 | L22: =MahindraLog!K142 -> 0.0057816857 | M22: =Industry!K143 -> 0.051867676 | N22: =IF(COUNT(C22:L22)=0,"N/M",MEDIAN(C22:L22)) -> 0.048819516
A23: Return on capital employed (post-tax) | B23: Returns (↑) | C23: =Tiger!K146 -> 0.094712109 | D23: =Allcargo!K146 -> 0.067070152 | E23: =BlueDart!K146 -> 0.13833211 | F23: =CONCOR!K146 -> 0.072251715 | G23: =JetFreight!K146 -> 0.036616476 | H23: =Patel!K146 -> 0.036368505 | I23: =Sical!K146 -> -0.061079075 | J23: =TCI!K146 -> 0.12781958 | K23: =Shreeji!K146 -> 0.07357899 | L23: =MahindraLog!K146 -> 0.040818271 | M23: =Industry!K147 -> 0.07527092 | N23: =IF(COUNT(C23:L23)=0,"N/M",MEDIAN(C23:L23)) -> 0.069660933
A24: Return on total shareholders' equity (ROE) | B24: Returns (↑) | C24: =Tiger!K147 -> 0.086615744 | D24: =Allcargo!K147 -> 0.12644432 | E24: =BlueDart!K147 -> 0.19434874 | F24: =CONCOR!K147 -> 0.085598326 | G24: =JetFreight!K147 -> -0.015603736 | H24: =Patel!K147 -> 0.048323836 | I24: =Sical!K147 -> -4.102302 | J24: =TCI!K147 -> 0.17114783 | K24: =Shreeji!K147 -> 0.12804549 | L24: =MahindraLog!K147 -> 0.0059799242 | M24: =Industry!K148 -> 0.086582652 | N24: =IF(COUNT(C24:L24)=0,"N/M",MEDIAN(C24:L24)) -> 0.086107035
A25: Price-earnings (P/E) ratio | B25: Valuation (-) | C25: =Tiger!K158 -> 18.205493 | D25: =Allcargo!K158 -> 134.42755 | E25: =BlueDart!K158 -> 60.639355 | F25: =CONCOR!K158 -> 41.785842 | G25: =JetFreight!K158 -> 203.63814 | H25: =Patel!K158 -> 207.37891 | I25: =Sical!K158 -> 10.200767 | J25: =TCI!K158 -> 15.551279 | K25: =Shreeji!K158 -> 24.35755 | L25: =MahindraLog!K158 -> 406.63754 | M25: =Industry!K159 -> 44.890973 | N25: =IF(COUNT(C25:L25)=0,"N/M",MEDIAN(C25:L25)) -> 51.212598
A26: Price-to-book (P/B) ratio | B26: Valuation (-) | C26: =Tiger!K159 -> 2.5994839 | D26: =Allcargo!K159 -> 1.8735547 | E26: =BlueDart!K159 -> 12.921371 | F26: =CONCOR!K159 -> 3.2852064 | G26: =JetFreight!K159 -> 1.7591522 | H26: =Patel!K159 -> 0.66414011 | I26: =Sical!K159 -> 9.5263998 | J26: =TCI!K159 -> 2.7172077 | K26: =Shreeji!K159 -> 3.4046469 | L26: =MahindraLog!K159 -> 6.0935807 | M26: =Industry!K160 -> 4.0055146 | N26: =IF(COUNT(C26:L26)=0,"N/M",MEDIAN(C26:L26)) -> 3.001207
A27: Dividend yield | B27: Valuation (-) | C27: =Tiger!K157 -> 0.00067832672 | D27: =Allcargo!K157 -> 0 | E27: =BlueDart!K157 -> 0.0042458934 | F27: =CONCOR!K157 -> 0.014493263 | G27: =JetFreight!K157 -> 0.00012704887 | H27: =Patel!K157 -> 0.010418909 | I27: =Sical!K157 -> 0 | J27: =TCI!K157 -> 0.0092816836 | K27: =Shreeji!K157 -> 0.0073395875 | L27: =MahindraLog!K157 -> 0.0053561347 | M27: =Industry!K158 -> 0.011025959 | N27: =IF(COUNT(C27:L27)=0,"N/M",MEDIAN(C27:L27)) -> 0.004801014
A28: EV / EBITDA | B28: Valuation (-) | C28: =Tiger!K160 -> 14.504126 | D28: =Allcargo!K160 -> 6.9677464 | E28: =BlueDart!K160 -> 16.489895 | F28: =CONCOR!K160 -> 20.793214 | G28: =JetFreight!K160 -> 11.526534 | H28: =Patel!K160 -> 11.464136 | I28: =Sical!K160 -> 38.516551 | J28: =TCI!K160 -> 12.403091 | K28: =Shreeji!K160 -> 12.750233 | L28: =MahindraLog!K160 -> 19.108693 | M28: =Industry!K161 -> 18.590864 | N28: =IF(COUNT(C28:L28)=0,"N/M",MEDIAN(C28:L28)) -> 13.627179
A31: B. Composite ranking on the 7-year averages (rank 1 = best among the 10 firms; ties share the better rank)
A32: Ratio | B32: Direction | C32: Tiger | D32: Allcargo | E32: Blue Dart | F32: CONCOR | G32: Jet Freight | H32: Patel | I32: Sical | J32: TCI | K32: Shreeji | L32: Mahindra Log.
A33: Current ratio | B33: higher is better | C33: =IF(ISNUMBER(C6),RANK(C6,$C$6:$L$6,0),"-") -> 3 | D33: =IF(ISNUMBER(D6),RANK(D6,$C$6:$L$6,0),"-") -> 7 | E33: =IF(ISNUMBER(E6),RANK(E6,$C$6:$L$6,0),"-") -> 9 | F33: =IF(ISNUMBER(F6),RANK(F6,$C$6:$L$6,0),"-") -> 4 | G33: =IF(ISNUMBER(G6),RANK(G6,$C$6:$L$6,0),"-") -> 6 | H33: =IF(ISNUMBER(H6),RANK(H6,$C$6:$L$6,0),"-") -> 1 | I33: =IF(ISNUMBER(I6),RANK(I6,$C$6:$L$6,0),"-") -> 10 | J33: =IF(ISNUMBER(J6),RANK(J6,$C$6:$L$6,0),"-") -> 5 | ... L33: =IF(ISNUMBER(L6),RANK(L6,$C$6:$L$6,0),"-") -> 8
A34: Cash flow from operations ratio | B34: higher is better | C34: =IF(ISNUMBER(C8),RANK(C8,$C$8:$L$8,0),"-") -> 7 | D34: =IF(ISNUMBER(D8),RANK(D8,$C$8:$L$8,0),"-") -> 5 | E34: =IF(ISNUMBER(E8),RANK(E8,$C$8:$L$8,0),"-") -> 3 | F34: =IF(ISNUMBER(F8),RANK(F8,$C$8:$L$8,0),"-") -> 1 | G34: =IF(ISNUMBER(G8),RANK(G8,$C$8:$L$8,0),"-") -> 10 | H34: =IF(ISNUMBER(H8),RANK(H8,$C$8:$L$8,0),"-") -> 9 | I34: =IF(ISNUMBER(I8),RANK(I8,$C$8:$L$8,0),"-") -> 8 | J34: =IF(ISNUMBER(J8),RANK(J8,$C$8:$L$8,0),"-") -> 2 | ... L34: =IF(ISNUMBER(L8),RANK(L8,$C$8:$L$8,0),"-") -> 6
A35: Debt-equity ratio | B35: lower is better | C35: =IF(ISNUMBER(C9),RANK(C9,$C$9:$L$9,1),"-") -> 3 | D35: =IF(ISNUMBER(D9),RANK(D9,$C$9:$L$9,1),"-") -> 5 | E35: =IF(ISNUMBER(E9),RANK(E9,$C$9:$L$9,1),"-") -> 7 | F35: =IF(ISNUMBER(F9),RANK(F9,$C$9:$L$9,1),"-") -> 1 | G35: =IF(ISNUMBER(G9),RANK(G9,$C$9:$L$9,1),"-") -> 9 | H35: =IF(ISNUMBER(H9),RANK(H9,$C$9:$L$9,1),"-") -> 4 | I35: =IF(ISNUMBER(I9),RANK(I9,$C$9:$L$9,1),"-") -> 10 | J35: =IF(ISNUMBER(J9),RANK(J9,$C$9:$L$9,1),"-") -> 2 | ... L35: =IF(ISNUMBER(L9),RANK(L9,$C$9:$L$9,1),"-") -> 6
A36: Interest coverage ratio | B36: higher is better | C36: =IF(ISNUMBER(C12),RANK(C12,$C$12:$L$12,0),"-") -> 3 | D36: =IF(ISNUMBER(D12),RANK(D12,$C$12:$L$12,0),"-") -> 6 | E36: =IF(ISNUMBER(E12),RANK(E12,$C$12:$L$12,0),"-") -> 5 | F36: =IF(ISNUMBER(F12),RANK(F12,$C$12:$L$12,0),"-") -> 1 | G36: =IF(ISNUMBER(G12),RANK(G12,$C$12:$L$12,0),"-") -> 9 | H36: =IF(ISNUMBER(H12),RANK(H12,$C$12:$L$12,0),"-") -> 4 | I36: =IF(ISNUMBER(I12),RANK(I12,$C$12:$L$12,0),"-") -> 10 | J36: =IF(ISNUMBER(J12),RANK(J12,$C$12:$L$12,0),"-") -> 2 | ... L36: =IF(ISNUMBER(L12),RANK(L12,$C$12:$L$12,0),"-") -> 8
A37: Average collection period (days) | B37: lower is better | C37: =IF(ISNUMBER(C14),RANK(C14,$C$14:$L$14,1),"-") -> 7 | D37: =IF(ISNUMBER(D14),RANK(D14,$C$14:$L$14,1),"-") -> 6 | E37: =IF(ISNUMBER(E14),RANK(E14,$C$14:$L$14,1),"-") -> 3 | F37: =IF(ISNUMBER(F14),RANK(F14,$C$14:$L$14,1),"-") -> 1 | G37: =IF(ISNUMBER(G14),RANK(G14,$C$14:$L$14,1),"-") -> 4 | H37: =IF(ISNUMBER(H14),RANK(H14,$C$14:$L$14,1),"-") -> 8 | I37: =IF(ISNUMBER(I14),RANK(I14,$C$14:$L$14,1),"-") -> 9 | J37: =IF(ISNUMBER(J14),RANK(J14,$C$14:$L$14,1),"-") -> 5 | ... L37: =IF(ISNUMBER(L14),RANK(L14,$C$14:$L$14,1),"-") -> 2
A38: Total assets turnover (times) | B38: higher is better | C38: =IF(ISNUMBER(C16),RANK(C16,$C$16:$L$16,0),"-") -> 2 | D38: =IF(ISNUMBER(D16),RANK(D16,$C$16:$L$16,0),"-") -> 6 | E38: =IF(ISNUMBER(E16),RANK(E16,$C$16:$L$16,0),"-") -> 8 | F38: =IF(ISNUMBER(F16),RANK(F16,$C$16:$L$16,0),"-") -> 9 | G38: =IF(ISNUMBER(G16),RANK(G16,$C$16:$L$16,0),"-") -> 1 | H38: =IF(ISNUMBER(H16),RANK(H16,$C$16:$L$16,0),"-") -> 5 | I38: =IF(ISNUMBER(I16),RANK(I16,$C$16:$L$16,0),"-") -> 10 | J38: =IF(ISNUMBER(J16),RANK(J16,$C$16:$L$16,0),"-") -> 7 | ... L38: =IF(ISNUMBER(L16),RANK(L16,$C$16:$L$16,0),"-") -> 3
A39: Operating EBITDA margin | B39: higher is better | C39: =IF(ISNUMBER(C18),RANK(C18,$C$18:$L$18,0),"-") -> 8 | D39: =IF(ISNUMBER(D18),RANK(D18,$C$18:$L$18,0),"-") -> 4 | E39: =IF(ISNUMBER(E18),RANK(E18,$C$18:$L$18,0),"-") -> 2 | F39: =IF(ISNUMBER(F18),RANK(F18,$C$18:$L$18,0),"-") -> 1 | G39: =IF(ISNUMBER(G18),RANK(G18,$C$18:$L$18,0),"-") -> 10 | H39: =IF(ISNUMBER(H18),RANK(H18,$C$18:$L$18,0),"-") -> 9 | I39: =IF(ISNUMBER(I18),RANK(I18,$C$18:$L$18,0),"-") -> 7 | J39: =IF(ISNUMBER(J18),RANK(J18,$C$18:$L$18,0),"-") -> 3 | ... L39: =IF(ISNUMBER(L18),RANK(L18,$C$18:$L$18,0),"-") -> 6
A40: Operating profit (EBIT) margin | B40: higher is better | C40: =IF(ISNUMBER(C19),RANK(C19,$C$19:$L$19,0),"-") -> 6 | D40: =IF(ISNUMBER(D19),RANK(D19,$C$19:$L$19,0),"-") -> 5 | E40: =IF(ISNUMBER(E19),RANK(E19,$C$19:$L$19,0),"-") -> 2 | F40: =IF(ISNUMBER(F19),RANK(F19,$C$19:$L$19,0),"-") -> 1 | G40: =IF(ISNUMBER(G19),RANK(G19,$C$19:$L$19,0),"-") -> 8 | H40: =IF(ISNUMBER(H19),RANK(H19,$C$19:$L$19,0),"-") -> 7 | I40: =IF(ISNUMBER(I19),RANK(I19,$C$19:$L$19,0),"-") -> 10 | J40: =IF(ISNUMBER(J19),RANK(J19,$C$19:$L$19,0),"-") -> 3 | ... L40: =IF(ISNUMBER(L19),RANK(L19,$C$19:$L$19,0),"-") -> 9
A41: Return on capital employed (post-tax) | B41: higher is better | C41: =IF(ISNUMBER(C23),RANK(C23,$C$23:$L$23,0),"-") -> 3 | D41: =IF(ISNUMBER(D23),RANK(D23,$C$23:$L$23,0),"-") -> 6 | E41: =IF(ISNUMBER(E23),RANK(E23,$C$23:$L$23,0),"-") -> 1 | F41: =IF(ISNUMBER(F23),RANK(F23,$C$23:$L$23,0),"-") -> 5 | G41: =IF(ISNUMBER(G23),RANK(G23,$C$23:$L$23,0),"-") -> 8 | H41: =IF(ISNUMBER(H23),RANK(H23,$C$23:$L$23,0),"-") -> 9 | I41: =IF(ISNUMBER(I23),RANK(I23,$C$23:$L$23,0),"-") -> 10 | J41: =IF(ISNUMBER(J23),RANK(J23,$C$23:$L$23,0),"-") -> 2 | ... L41: =IF(ISNUMBER(L23),RANK(L23,$C$23:$L$23,0),"-") -> 7
A42: Return on total shareholders' equity (ROE) | B42: higher is better | C42: =IF(ISNUMBER(C24),RANK(C24,$C$24:$L$24,0),"-") -> 5 | D42: =IF(ISNUMBER(D24),RANK(D24,$C$24:$L$24,0),"-") -> 4 | E42: =IF(ISNUMBER(E24),RANK(E24,$C$24:$L$24,0),"-") -> 1 | F42: =IF(ISNUMBER(F24),RANK(F24,$C$24:$L$24,0),"-") -> 6 | G42: =IF(ISNUMBER(G24),RANK(G24,$C$24:$L$24,0),"-") -> 9 | H42: =IF(ISNUMBER(H24),RANK(H24,$C$24:$L$24,0),"-") -> 7 | I42: =IF(ISNUMBER(I24),RANK(I24,$C$24:$L$24,0),"-") -> 10 | J42: =IF(ISNUMBER(J24),RANK(J24,$C$24:$L$24,0),"-") -> 2 | ... L42: =IF(ISNUMBER(L24),RANK(L24,$C$24:$L$24,0),"-") -> 8
A43: Composite score (average rank) | B43: lower is better | C43: =AVERAGE(C33:C42) -> 4.7 | D43: =AVERAGE(D33:D42) -> 5.4 | E43: =AVERAGE(E33:E42) -> 4.1 | F43: =AVERAGE(F33:F42) -> 3 | G43: =AVERAGE(G33:G42) -> 7.4 | H43: =AVERAGE(H33:H42) -> 6.3 | I43: =AVERAGE(I33:I42) -> 9.4 | J43: =AVERAGE(J33:J42) -> 3.3 | ... L43: =AVERAGE(L33:L42) -> 6.3
...

Sheet Industry_Compare
A1: Industry comparison - every ratio, every firm, FY2020-FY2026
A2: Industry (aggregate) = ratio on the summed financials of the 10 firms (size-weighted). Mean / median / SD / min / max = simple statistics of the 10 firm ratios (N/M and N/C values are ignored). Assessment and rank compare each firm's 7-year average with the 10-firm median (the typical-firm benchmark).
A4: Firm / statistic | B4: FY2020 | C4: FY2021 | D4: FY2022 | E4: FY2023 | F4: FY2024 | G4: FY2025 | H4: FY2026 | I4: 7-Yr Average | J4: 7-yr avg vs median | K4: Assessment | L4: Rank (1 = best)
A6: 1.1 Net working capital [Current assets - Current liabilities] - Liquidity; no normative direction
A7: Tiger | B7: =Tiger!D94 -> 79.44 | C7: =Tiger!E94 -> 48.16 | D7: =Tiger!F94 -> 61.36 | E7: =Tiger!G94 -> 84.64 | F7: =Tiger!H94 -> 102.6 | G7: =Tiger!I94 -> 151.77 | H7: =Tiger!J94 -> 187.87 | I7: =Tiger!K94 -> 102.26286 | J7: =IF(AND(ISNUMBER(I7),ISNUMBER(I$19)),IF(I7>I$19,"Above",IF(I7<I$19,"Below","At median")),"-") -> Below | K7: - | L7: -
A8: Allcargo | B8: =Allcargo!D94 -> 1002.04 | C8: =Allcargo!E94 -> 857.7 | D8: =Allcargo!F94 -> 1417.79 | E8: =Allcargo!G94 -> 1265.14 | F8: =Allcargo!H94 -> 1242.73 | G8: =Allcargo!I94 -> 578 | H8: =Allcargo!J94 -> 481 | I8: =Allcargo!K94 -> 977.77143 | J8: =IF(AND(ISNUMBER(I8),ISNUMBER(I$19)),IF(I8>I$19,"Above",IF(I8<I$19,"Below","At median")),"-") -> Above | K8: - | L8: -
A9: Blue Dart | B9: =BlueDart!D94 -> -662.18 | C9: =BlueDart!E94 -> 374.18 | D9: =BlueDart!F94 -> 224.54 | E9: =BlueDart!G94 -> 252.87 | F9: =BlueDart!H94 -> 236.54 | G9: =BlueDart!I94 -> 289.72 | H9: =BlueDart!J94 -> 443.88 | I9: =BlueDart!K94 -> 165.65 | J9: =IF(AND(ISNUMBER(I9),ISNUMBER(I$19)),IF(I9>I$19,"Above",IF(I9<I$19,"Below","At median")),"-") -> Above | K9: - | L9: -
A10: CONCOR | B10: =CONCOR!D94 -> 2626.3 | C10: =CONCOR!E94 -> 3063.63 | D10: =CONCOR!F94 -> 3805.64 | E10: =CONCOR!G94 -> 4333.98 | F10: =CONCOR!H94 -> 4747.44 | G10: =CONCOR!I94 -> 4689.41 | H10: =CONCOR!J94 -> 4759.67 | I10: =CONCOR!K94 -> 4003.7243 | J10: =IF(AND(ISNUMBER(I10),ISNUMBER(I$19)),IF(I10>I$19,"Above",IF(I10<I$19,"Below","At median")),"-") -> Above | K10: - | L10: -
A11: Jet Freight | B11: =JetFreight!D94 -> 39.16 | C11: =JetFreight!E94 -> 23.78 | D11: =JetFreight!F94 -> 42.17 | E11: =JetFreight!G94 -> 92.29 | F11: =JetFreight!H94 -> 90.86 | G11: =JetFreight!I94 -> 103.78 | H11: =JetFreight!J94 -> 122.24 | I11: =JetFreight!K94 -> 73.468571 | J11: =IF(AND(ISNUMBER(I11),ISNUMBER(I$19)),IF(I11>I$19,"Above",IF(I11<I$19,"Below","At median")),"-") -> Below | K11: - | L11: -
A12: Patel | B12: =Patel!D94 -> 115.87 | C12: =Patel!E94 -> 115.04 | D12: =Patel!F94 -> 102.28 | E12: =Patel!G94 -> 88.52 | F12: =Patel!H94 -> 90.18 | G12: =Patel!I94 -> 83.19 | H12: =Patel!J94 -> 79.32 | I12: =Patel!K94 -> 96.342857 | J12: =IF(AND(ISNUMBER(I12),ISNUMBER(I$19)),IF(I12>I$19,"Above",IF(I12<I$19,"Below","At median")),"-") -> Below | K12: - | L12: -
A13: Sical | B13: =Sical!D94 -> -459.35 | C13: =Sical!E94 -> -646.28 | D13: =Sical!F94 -> -337.55 | E13: =Sical!G94 -> -68.93 | F13: =Sical!H94 -> -32.09 | G13: =Sical!I94 -> -51.8 | H13: =Sical!J94 -> 40.73 | I13: =Sical!K94 -> -222.18143 | J13: =IF(AND(ISNUMBER(I13),ISNUMBER(I$19)),IF(I13>I$19,"Above",IF(I13<I$19,"Below","At median")),"-") -> Below | K13: - | L13: -
A14: TCI | B14: =TCI!D94 -> 517.29 | C14: =TCI!E94 -> 507.36 | D14: =TCI!F94 -> 525.15 | E14: =TCI!G94 -> 690.52 | F14: =TCI!H94 -> 684.09 | G14: =TCI!I94 -> 766.74 | H14: =TCI!J94 -> 855.89 | I14: =TCI!K94 -> 649.57714 | J14: =IF(AND(ISNUMBER(I14),ISNUMBER(I$19)),IF(I14>I$19,"Above",IF(I14<I$19,"Below","At median")),"-") -> Above | K14: - | L14: -
A15: Shreeji | B15: =Shreeji!D94 -> 43.83 | C15: =Shreeji!E94 -> 46.23 | D15: =Shreeji!F94 -> 56.35 | E15: =Shreeji!G94 -> 56.1 | F15: =Shreeji!H94 -> 66.91 | G15: =Shreeji!I94 -> 65.55 | H15: =Shreeji!J94 -> 72.95 | I15: =Shreeji!K94 -> 58.274286 | J15: =IF(AND(ISNUMBER(I15),ISNUMBER(I$19)),IF(I15>I$19,"Above",IF(I15<I$19,"Below","At median")),"-") -> Below | K15: - | L15: -
A16: Mahindra Log. | B16: =MahindraLog!D94 -> 496.81 | C16: =MahindraLog!E94 -> 418.69 | D16: =MahindraLog!F94 -> 316.78 | E16: =MahindraLog!G94 -> 462.39 | F16: =MahindraLog!H94 -> 373.47 | G16: =MahindraLog!I94 -> 308.71 | H16: =MahindraLog!J94 -> 527.87 | I16: =MahindraLog!K94 -> 414.96 | J16: =IF(AND(ISNUMBER(I16),ISNUMBER(I$19)),IF(I16>I$19,"Above",IF(I16<I$19,"Below","At median")),"-") -> Above | K16: - | L16: -
A17: Industry (aggregate) | B17: =Industry!D95 -> 3799.21 | C17: =Industry!E95 -> 4808.49 | D17: =Industry!F95 -> 6214.51 | E17: =Industry!G95 -> 7257.52 | F17: =Industry!H95 -> 7602.73 | G17: =Industry!I95 -> 6985.07 | H17: =Industry!J95 -> 7571.42 | I17: =Industry!K95 -> 6319.85
A18: Mean (10 firms) | B18: =IF(COUNT(B7:B16)=0,"N/M",AVERAGE(B7:B16)) -> 379.921 | C18: =IF(COUNT(C7:C16)=0,"N/M",AVERAGE(C7:C16)) -> 480.849 | D18: =IF(COUNT(D7:D16)=0,"N/M",AVERAGE(D7:D16)) -> 621.451 | E18: =IF(COUNT(E7:E16)=0,"N/M",AVERAGE(E7:E16)) -> 725.752 | F18: =IF(COUNT(F7:F16)=0,"N/M",AVERAGE(F7:F16)) -> 760.273 | G18: =IF(COUNT(G7:G16)=0,"N/M",AVERAGE(G7:G16)) -> 698.507 | H18: =IF(COUNT(H7:H16)=0,"N/M",AVERAGE(H7:H16)) -> 757.142 | I18: =IF(COUNT(I7:I16)=0,"N/M",AVERAGE(I7:I16)) -> 631.985
A19: Median (10 firms) | B19: =IF(COUNT(B7:B16)=0,"N/M",MEDIAN(B7:B16)) -> 97.655 | C19: =IF(COUNT(C7:C16)=0,"N/M",MEDIAN(C7:C16)) -> 244.61 | D19: =IF(COUNT(D7:D16)=0,"N/M",MEDIAN(D7:D16)) -> 163.41 | E19: =IF(COUNT(E7:E16)=0,"N/M",MEDIAN(E7:E16)) -> 172.58 | F19: =IF(COUNT(F7:F16)=0,"N/M",MEDIAN(F7:F16)) -> 169.57 | G19: =IF(COUNT(G7:G16)=0,"N/M",MEDIAN(G7:G16)) -> 220.745 | H19: =IF(COUNT(H7:H16)=0,"N/M",MEDIAN(H7:H16)) -> 315.875 | I19: =IF(COUNT(I7:I16)=0,"N/M",MEDIAN(I7:I16)) -> 133.95643
A20: Standard deviation | B20: =IF(COUNT(B7:B16)<2,"N/M",STDEV(B7:B16)) -> 921.66644 | C20: =IF(COUNT(C7:C16)<2,"N/M",STDEV(C7:C16)) -> 989.83617 | D20: =IF(COUNT(D7:D16)<2,"N/M",STDEV(D7:D16)) -> 1210.6326 | E20: =IF(COUNT(E7:E16)<2,"N/M",STDEV(E7:E16)) -> 1329.2765 | F20: =IF(COUNT(F7:F16)<2,"N/M",STDEV(F7:F16)) -> 1452.8992 | G20: =IF(COUNT(G7:G16)<2,"N/M",STDEV(G7:G16)) -> 1424.4049 | H20: =IF(COUNT(H7:H16)<2,"N/M",STDEV(H7:H16)) -> 1430.8084 | I20: =IF(COUNT(I7:I16)<2,"N/M",STDEV(I7:I16)) -> 1233.3907
A21: Minimum | B21: =IF(COUNT(B7:B16)=0,"N/M",MIN(B7:B16)) -> -662.18 | C21: =IF(COUNT(C7:C16)=0,"N/M",MIN(C7:C16)) -> -646.28 | D21: =IF(COUNT(D7:D16)=0,"N/M",MIN(D7:D16)) -> -337.55 | E21: =IF(COUNT(E7:E16)=0,"N/M",MIN(E7:E16)) -> -68.93 | F21: =IF(COUNT(F7:F16)=0,"N/M",MIN(F7:F16)) -> -32.09 | G21: =IF(COUNT(G7:G16)=0,"N/M",MIN(G7:G16)) -> -51.8 | H21: =IF(COUNT(H7:H16)=0,"N/M",MIN(H7:H16)) -> 40.73 | I21: =IF(COUNT(I7:I16)=0,"N/M",MIN(I7:I16)) -> -222.18143
A22: Maximum | B22: =IF(COUNT(B7:B16)=0,"N/M",MAX(B7:B16)) -> 2626.3 | C22: =IF(COUNT(C7:C16)=0,"N/M",MAX(C7:C16)) -> 3063.63 | D22: =IF(COUNT(D7:D16)=0,"N/M",MAX(D7:D16)) -> 3805.64 | E22: =IF(COUNT(E7:E16)=0,"N/M",MAX(E7:E16)) -> 4333.98 | F22: =IF(COUNT(F7:F16)=0,"N/M",MAX(F7:F16)) -> 4747.44 | G22: =IF(COUNT(G7:G16)=0,"N/M",MAX(G7:G16)) -> 4689.41 | H22: =IF(COUNT(H7:H16)=0,"N/M",MAX(H7:H16)) -> 4759.67 | I22: =IF(COUNT(I7:I16)=0,"N/M",MAX(I7:I16)) -> 4003.7243
A24: 1.2 Current ratio [Current assets / Current liabilities] - Liquidity; higher is better
A25: Tiger | B25: =Tiger!D95 -> 6.047014 | C25: =Tiger!E95 -> 2.7896693 | D25: =Tiger!F95 -> 2.310551 | E25: =Tiger!G95 -> 4.8683729 | F25: =Tiger!H95 -> 5.9541284 | G25: =Tiger!I95 -> 7.5958279 | H25: =Tiger!J95 -> 4.6170581 | I25: =Tiger!K95 -> 4.8832317 | J25: =IF(AND(ISNUMBER(I25),ISNUMBER(I$37)),IF(I25>I$37,"Above",IF(I25<I$37,"Below","At median")),"-") -> Above | K25: =IF(J25="Above","Better",IF(J25="Below","Weaker",IF(J25="At median","In line","-"))) -> Better | L25: =IF(ISNUMBER(I25),RANK(I25,I$25:I$34,0),"-") -> 3
A26: Allcargo | B26: =Allcargo!D95 -> 1.6456859 | C26: =Allcargo!E95 -> 1.2893373 | D26: =Allcargo!F95 -> 1.3437125 | E26: =Allcargo!G95 -> 1.3908215 | F26: =Allcargo!H95 -> 1.4445132 | G26: =Allcargo!I95 -> 2.4522613 | H26: =Allcargo!J95 -> 2.0255864 | I26: =Allcargo!K95 -> 1.6559883 | J26: =IF(AND(ISNUMBER(I26),ISNUMBER(I$37)),IF(I26>I$37,"Above",IF(I26<I$37,"Below","At median")),"-") -> Below | K26: =IF(J26="Above","Better",IF(J26="Below","Weaker",IF(J26="At median","In line","-"))) -> Weaker | L26: =IF(ISNUMBER(I26),RANK(I26,I$25:I$34,0),"-") -> 7
A27: Blue Dart | B27: =BlueDart!D95 -> 0.59123682 | C27: =BlueDart!E95 -> 1.4776847 | D27: =BlueDart!F95 -> 1.2520571 | E27: =BlueDart!G95 -> 1.2738644 | F27: =BlueDart!H95 -> 1.2317475 | G27: =BlueDart!I95 -> 1.2641671 | H27: =BlueDart!J95 -> 1.3674138 | I27: =BlueDart!K95 -> 1.2083102 | J27: =IF(AND(ISNUMBER(I27),ISNUMBER(I$37)),IF(I27>I$37,"Above",IF(I27<I$37,"Below","At median")),"-") -> Below | K27: =IF(J27="Above","Better",IF(J27="Below","Weaker",IF(J27="At median","In line","-"))) -> Weaker | L27: =IF(ISNUMBER(I27),RANK(I27,I$25:I$34,0),"-") -> 9
A28: CONCOR | B28: =CONCOR!D95 -> 2.5701338 | C28: =CONCOR!E95 -> 3.042066 | D28: =CONCOR!F95 -> 3.5179069 | E28: =CONCOR!G95 -> 3.9676867 | F28: =CONCOR!H95 -> 4.7198355 | G28: =CONCOR!I95 -> 4.7991234 | H28: =CONCOR!J95 -> 4.7511388 | I28: =CONCOR!K95 -> 3.9096987 | J28: =IF(AND(ISNUMBER(I28),ISNUMBER(I$37)),IF(I28>I$37,"Above",IF(I28<I$37,"Below","At median")),"-") -> Above | K28: =IF(J28="Above","Better",IF(J28="Below","Weaker",IF(J28="At median","In line","-"))) -> Better | L28: =IF(ISNUMBER(I28),RANK(I28,I$25:I$34,0),"-") -> 4
A29: Jet Freight | B29: =JetFreight!D95 -> 2.1770364 | C29: =JetFreight!E95 -> 1.5218345 | D29: =JetFreight!F95 -> 2.1581983 | E29: =JetFreight!G95 -> 4.0013008 | F29: =JetFreight!H95 -> 2.7379495 | G29: =JetFreight!I95 -> 2.9950019 | H29: =JetFreight!J95 -> 3.5881855 | I29: =JetFreight!K95 -> 2.7399296 | J29: =IF(AND(ISNUMBER(I29),ISNUMBER(I$37)),IF(I29>I$37,"Above",IF(I29<I$37,"Below","At median")),"-") -> Below | K29: =IF(J29="Above","Better",IF(J29="Below","Weaker",IF(J29="At median","In line","-"))) -> Weaker | L29: =IF(ISNUMBER(I29),RANK(I29,I$25:I$34,0),"-") -> 6
A30: Patel | B30: =Patel!D95 -> 5.5191108 | C30: =Patel!E95 -> 10.618729 | D30: =Patel!F95 -> 8.4062274 | E30: =Patel!G95 -> 4.8155172 | F30: =Patel!H95 -> 2.8559374 | G30: =Patel!I95 -> 3.4914645 | H30: =Patel!J95 -> 3.3649374 | I30: =Patel!K95 -> 5.5817034 | J30: =IF(AND(ISNUMBER(I30),ISNUMBER(I$37)),IF(I30>I$37,"Above",IF(I30<I$37,"Below","At median")),"-") -> Above | K30: =IF(J30="Above","Better",IF(J30="Below","Weaker",IF(J30="At median","In line","-"))) -> Better | L30: =IF(ISNUMBER(I30),RANK(I30,I$25:I$34,0),"-") -> 1
A31: Sical | B31: =Sical!D95 -> 0.53880059 | C31: =Sical!E95 -> 0.43040965 | D31: =Sical!F95 -> 0.53771673 | E31: =Sical!G95 -> 0.73076322 | F31: =Sical!H95 -> 0.86142419 | G31: =Sical!I95 -> 0.79756136 | H31: =Sical!J95 -> 1.1402597 | I31: =Sical!K95 -> 0.7195622 | J31: =IF(AND(ISNUMBER(I31),ISNUMBER(I$37)),IF(I31>I$37,"Above",IF(I31<I$37,"Below","At median")),"-") -> Below | K31: =IF(J31="Above","Better",IF(J31="Below","Weaker",IF(J31="At median","In line","-"))) -> Weaker | L31: =IF(ISNUMBER(I31),RANK(I31,I$25:I$34,0),"-") -> 10
A32: TCI | B32: =TCI!D95 -> 3.1791642 | C32: =TCI!E95 -> 2.8679037 | D32: =TCI!F95 -> 2.7474711 | E32: =TCI!G95 -> 3.2474207 | F32: =TCI!H95 -> 3.2510365 | G32: =TCI!I95 -> 2.4267054 | H32: =TCI!J95 -> 2.4182809 | I32: =TCI!K95 -> 2.8768546 | J32: =IF(AND(ISNUMBER(I32),ISNUMBER(I$37)),IF(I32>I$37,"Above",IF(I32<I$37,"Below","At median")),"-") -> Above | K32: =IF(J32="Above","Better",IF(J32="Below","Weaker",IF(J32="At median","In line","-"))) -> Better | L32: =IF(ISNUMBER(I32),RANK(I32,I$25:I$34,0),"-") -> 5
A33: Shreeji | B33: =Shreeji!D95 -> 6.1143524 | C33: =Shreeji!E95 -> 5.4709865 | D33: =Shreeji!F95 -> 5.4686757 | E33: =Shreeji!G95 -> 4.1375839 | F33: =Shreeji!H95 -> 4.7823629 | G33: =Shreeji!I95 -> 4.9369369 | H33: =Shreeji!J95 -> 4.7719752 | I33: =Shreeji!K95 -> 5.0975533 | J33: =IF(AND(ISNUMBER(I33),ISNUMBER(I$37)),IF(I33>I$37,"Above",IF(I33<I$37,"Below","At median")),"-") -> Above | K33: =IF(J33="Above","Better",IF(J33="Below","Weaker",IF(J33="At median","In line","-"))) -> Better | L33: =IF(ISNUMBER(I33),RANK(I33,I$25:I$34,0),"-") -> 2
A34: Mahindra Log. | B34: =MahindraLog!D95 -> 1.7350456 | C34: =MahindraLog!E95 -> 1.4929302 | D34: =MahindraLog!F95 -> 1.30859 | E34: =MahindraLog!G95 -> 1.3995697 | F34: =MahindraLog!H95 -> 1.2998699 | G34: =MahindraLog!I95 -> 1.2426698 | H34: =MahindraLog!J95 -> 1.4122438 | I34: =MahindraLog!K95 -> 1.4129884 | J34: =IF(AND(ISNUMBER(I34),ISNUMBER(I$37)),IF(I34>I$37,"Above",IF(I34<I$37,"Below","At median")),"-") -> Below | K34: =IF(J34="Above","Better",IF(J34="Below","Weaker",IF(J34="At median","In line","-"))) -> Weaker | L34: =IF(ISNUMBER(I34),RANK(I34,I$25:I$34,0),"-") -> 8
A35: Industry (aggregate) | B35: =Industry!D96 -> 1.5556838 | C35: =Industry!E96 -> 1.6328318 | D35: =Industry!F96 -> 1.7147979 | E35: =Industry!G96 -> 1.9761212 | F35: =Industry!H96 -> 2.0841188 | G35: =Industry!I96 -> 2.4198509 | H35: =Industry!J96 -> 2.4360563 | I35: =Industry!K96 -> 1.9742087
A36: Mean (10 firms) | B36: =IF(COUNT(B25:B34)=0,"N/M",AVERAGE(B25:B34)) -> 3.011758 | C36: =IF(COUNT(C25:C34)=0,"N/M",AVERAGE(C25:C34)) -> 3.1001551 | D36: =IF(COUNT(D25:D34)=0,"N/M",AVERAGE(D25:D34)) -> 2.9051107 | E36: =IF(COUNT(E25:E34)=0,"N/M",AVERAGE(E25:E34)) -> 2.9832901 | F36: =IF(COUNT(F25:F34)=0,"N/M",AVERAGE(F25:F34)) -> 2.9138805 | G36: =IF(COUNT(G25:G34)=0,"N/M",AVERAGE(G25:G34)) -> 3.200172 | H36: =IF(COUNT(H25:H34)=0,"N/M",AVERAGE(H25:H34)) -> 2.945708 | I36: =IF(COUNT(I25:I34)=0,"N/M",AVERAGE(I25:I34)) -> 3.0085821
A37: Median (10 firms) | B37: =IF(COUNT(B25:B34)=0,"N/M",MEDIAN(B25:B34)) -> 2.3735851 | C37: =IF(COUNT(C25:C34)=0,"N/M",MEDIAN(C25:C34)) -> 2.1557519 | D37: =IF(COUNT(D25:D34)=0,"N/M",MEDIAN(D25:D34)) -> 2.2343747 | E37: =IF(COUNT(E25:E34)=0,"N/M",MEDIAN(E25:E34)) -> 3.6075537 | F37: =IF(COUNT(F25:F34)=0,"N/M",MEDIAN(F25:F34)) -> 2.7969435 | G37: =IF(COUNT(G25:G34)=0,"N/M",MEDIAN(G25:G34)) -> 2.7236316 | H37: =IF(COUNT(H25:H34)=0,"N/M",MEDIAN(H25:H34)) -> 2.8916092 | I37: =IF(COUNT(I25:I34)=0,"N/M",MEDIAN(I25:I34)) -> 2.8083921
A38: Standard deviation | B38: =IF(COUNT(B25:B34)<2,"N/M",STDEV(B25:B34)) -> 2.1477661 | C38: =IF(COUNT(C25:C34)<2,"N/M",STDEV(C25:C34)) -> 2.9891803 | D38: =IF(COUNT(D25:D34)<2,"N/M",STDEV(D25:D34)) -> 2.3914171 | E38: =IF(COUNT(E25:E34)<2,"N/M",STDEV(E25:E34)) -> 1.6110133 | F38: =IF(COUNT(F25:F34)<2,"N/M",STDEV(F25:F34)) -> 1.762259 | G38: =IF(COUNT(G25:G34)<2,"N/M",STDEV(G25:G34)) -> 2.0958113 | H38: =IF(COUNT(H25:H34)<2,"N/M",STDEV(H25:H34)) -> 1.460736 | I38: =IF(COUNT(I25:I34)<2,"N/M",STDEV(I25:I34)) -> 1.7718986
A39: Minimum | B39: =IF(COUNT(B25:B34)=0,"N/M",MIN(B25:B34)) -> 0.53880059 | C39: =IF(COUNT(C25:C34)=0,"N/M",MIN(C25:C34)) -> 0.43040965 | D39: =IF(COUNT(D25:D34)=0,"N/M",MIN(D25:D34)) -> 0.53771673 | E39: =IF(COUNT(E25:E34)=0,"N/M",MIN(E25:E34)) -> 0.73076322 | F39: =IF(COUNT(F25:F34)=0,"N/M",MIN(F25:F34)) -> 0.86142419 | G39: =IF(COUNT(G25:G34)=0,"N/M",MIN(G25:G34)) -> 0.79756136 | H39: =IF(COUNT(H25:H34)=0,"N/M",MIN(H25:H34)) -> 1.1402597 | I39: =IF(COUNT(I25:I34)=0,"N/M",MIN(I25:I34)) -> 0.7195622
A40: Maximum | B40: =IF(COUNT(B25:B34)=0,"N/M",MAX(B25:B34)) -> 6.1143524 | C40: =IF(COUNT(C25:C34)=0,"N/M",MAX(C25:C34)) -> 10.618729 | D40: =IF(COUNT(D25:D34)=0,"N/M",MAX(D25:D34)) -> 8.4062274 | E40: =IF(COUNT(E25:E34)=0,"N/M",MAX(E25:E34)) -> 4.8683729 | F40: =IF(COUNT(F25:F34)=0,"N/M",MAX(F25:F34)) -> 5.9541284 | G40: =IF(COUNT(G25:G34)=0,"N/M",MAX(G25:G34)) -> 7.5958279 | H40: =IF(COUNT(H25:H34)=0,"N/M",MAX(H25:H34)) -> 4.7719752 | I40: =IF(COUNT(I25:I34)=0,"N/M",MAX(I25:I34)) -> 5.5817034
A42: 1.3 Quick (acid-test) ratio [Quick assets / Current liabilities] - Liquidity; higher is better
A43: Tiger | B43: =Tiger!D96 -> 4.5463787 | C43: =Tiger!E96 -> 1.8784838 | D43: =Tiger!F96 -> 2.1405382 | E43: =Tiger!G96 -> 4.6480804 | F43: =Tiger!H96 -> 5.385804 | G43: =Tiger!I96 -> 6.6857888 | H43: =Tiger!J96 -> 3.8983442 | I43: =Tiger!K96 -> 4.1690597 | J43: =IF(AND(ISNUMBER(I43),ISNUMBER(I$55)),IF(I43>I$55,"Above",IF(I43<I$55,"Below","At median")),"-") -> Above | K43: =IF(J43="Above","Better",IF(J43="Below","Weaker",IF(J43="At median","In line","-"))) -> Better | L43: =IF(ISNUMBER(I43),RANK(I43,I$43:I$52,0),"-") -> 2
