Workbook

Sheet ReadMe
A1: DECISION MAKING USING FINANCIAL STATEMENTS - Group Project: Excel workings
A2: Industry: Indian listed logistics & freight-transport services | 10 firms | 7 financial years FY2020-FY2026 (FY2019 used only as opening balance for averages)
A3: 1. Purpose
A4: Ratio analysis (liquidity, leverage, turnover, profitability, valuation), industry comparison, 7-year trend analysis, DuPont, common-size, trend-index and statistical analysis for 10 listed logistics companies, under the assumption that these 10 firms constitute the entire industry. Every industry benchmark is computed only from these 10 firms.
A5: 2. Sheet map
A6: Firm_Profiles - the 10 firms, segments, business models and quantitative evidence of operating homogeneity (supports the industry/firm-selection justification).
A7: Scorecard - 24 key ratios for every firm vs the industry aggregate and the 10-firm median; green = better than median, red = weaker (FY2026 and 7-year average).
A8: Industry_Compare - every ratio (76) for every firm and year with Industry aggregate, Mean, Median, SD, Min, Max, position vs median, assessment and rank.
A9: Statistics - descriptive statistics, correlation matrix, multiple regression, paired t-tests (FY2020 vs FY2026), Welch t-test (asset-light vs asset-heavy), two-way ANOVA, growth/stability.
A10: Panel - 70 firm-year observations of key variables (linked), the data used by the Statistics sheet.
A11: Industry - aggregate of the 10 firms (sum of each line item) with the same ratio formulas: the size-weighted industry ratio.
A12: Tiger ... MahindraLog - one sheet per company: raw statements (inputs), derived items, all ratios, DuPont, growth, common-size P&L and balance sheet, trend index (FY2020 = 100). Columns K-M: 7-year average, change FY26 vs FY20, linear trend slope per year.
... A32: This workbook was built with the assistance of Claude (Anthropic) - an AI assistant - which wrote the formulas and layout from the group's data file and the course formula list. All inputs come from the group-supplied Screener.in export; every ratio is a live formula and was cross-checked against an independent Python computation (all cells matched). The group remains responsible for the interpretation.

Sheet Firm_Profiles
A1: FIRM SELECTION - the 10 listed Indian logistics companies and evidence of operating homogeneity
A2: Columns H-P are linked to the company sheets. Low dispersion in cost structure (direct operating cost dominant, negligible inventory, receivable-led working capital) shows the firms share one operating model; asset intensity shows the different value propositions.
A4: # | B4: Company | C4: NSE symbol | D4: BSE code | E4: Segment / value proposition | F4: Business model | G4: Asset group (vs median NB/TA) | H4: Sales FY2026 (Rs cr) | I4: Total assets FY2026 (Rs cr) | J4: Market cap FY2026 (Rs cr) | K4: Sales CAGR FY20-26 | L4: Direct operating cost % sales (7-yr) | M4: Employee cost % sales (7-yr) | N4: Inventory % total assets (7-yr) | O4: Receivables % total assets (7-yr) | P4: Net block % total assets (7-yr) | Q4: Operating EBITDA margin (7-yr)
A5: 1 | B5: Tiger Logistics (India) Ltd | C5: TIGERLOGS | D5: 536264 | E5: International freight forwarding (sea & air), customs brokerage, project cargo | F5: Asset-light forwarder | G5: =IF(P5>=MEDIAN($P$5:$P$14),"Asset-heavy","Asset-light") -> Asset-light | H5: =Tiger!J9 -> 572.82 | I5: =Tiger!J35 -> 262.62 | J5: =Tiger!J69 -> 252.623 | K5: =(Tiger!J9/Tiger!D9)^(1/6)-1 -> 0.11290974 | L5: =Tiger!K127 -> 0.90008469 | M5: =Tiger!K129 -> 0.042590791 | N5: =Tiger!K200 -> 0 | O5: =Tiger!K199 -> 0.534418 | P5: =Tiger!K195 -> 0.066850107 | Q5: =Tiger!K121 -> 0.029629489
A6: 2 | B6: Allcargo Logistics Ltd | C6: ALLCARGO | D6: 532749 | E6: LCL consolidation/NVOCC (international business demerged to Allcargo Global w.e.f. 1-Nov-2025); domestic express & contract logistics | F6: Asset-light network operator | G6: =IF(P6>=MEDIAN($P$5:$P$14),"Asset-heavy","Asset-light") -> Asset-heavy | H6: =Allcargo!J9 -> 2058 | I6: =Allcargo!J35 -> 1736 | J6: =Allcargo!J69 -> 1075.4204 | K6: =(Allcargo!J9/Allcargo!D9)^(1/6)-1 -> -0.19109651 | L6: =Allcargo!K127 -> 0.76369076 | M6: =Allcargo!K129 -> 0.11942794 | N6: =Allcargo!K200 -> 0.00063859079 | O6: =Allcargo!K199 -> 0.27001652 | P6: =Allcargo!K195 -> 0.39214748 | Q6: =Allcargo!K121 -> 0.073607981
A7: 3 | B7: Blue Dart Express Ltd | C7: BLUEDART | D7: 526612 | E7: Express air & ground courier and integrated transport (DHL Group); dedicated freighter fleet | F7: Asset-heavy express network | G7: =IF(P7>=MEDIAN($P$5:$P$14),"Asset-heavy","Asset-light") -> Asset-heavy | H7: =BlueDart!J9 -> 6140.88 | I7: =BlueDart!J35 -> 4126.85 | J7: =BlueDart!J69 -> 11250.39 | K7: =(BlueDart!J9/BlueDart!D9)^(1/6)-1 -> 0.11620728 | L7: =BlueDart!K127 -> 0.57413445 | M7: =BlueDart!K129 -> 0.18587756 | N7: =BlueDart!K200 -> 0.012623821 | O7: =BlueDart!K199 -> 0.20174168 | P7: =BlueDart!K195 -> 0.52080847 | Q7: =BlueDart!K121 -> 0.17658992
A8: 4 | B8: Container Corporation of India Ltd | C8: CONCOR | D8: 531344 | E8: Rail-based EXIM & domestic container logistics, ICDs/CFSs (Navratna CPSE, Ministry of Railways) | F8: Asset-heavy multimodal | G8: =IF(P8>=MEDIAN($P$5:$P$14),"Asset-heavy","Asset-light") -> Asset-heavy | H8: =CONCOR!J9 -> 9078.97 | I8: =CONCOR!J35 -> 15175.78 | J8: =CONCOR!J69 -> 32390.848 | K8: =(CONCOR!J9/CONCOR!D9)^(1/6)-1 -> 0.056454767 | L8: =CONCOR!K127 -> 0.65386661 | M8: =CONCOR!K129 -> 0.05554146 | N8: =CONCOR!K200 -> 0.0028375504 | O8: =CONCOR!K199 -> 0.020044213 | P8: =CONCOR!K195 -> 0.44613792 | Q8: =CONCOR!K121 -> 0.21971019
A9: 5 | B9: Jet Freight Logistics Ltd | C9: JETFREIGHT | D9: 543420 | E9: International air & ocean freight forwarding (incl. perishables), customs clearance | F9: Asset-light forwarder | G9: =IF(P9>=MEDIAN($P$5:$P$14),"Asset-heavy","Asset-light") -> Asset-light | H9: =JetFreight!J9 -> 444.08 | I9: =JetFreight!J35 -> 194.09 | J9: =JetFreight!J69 -> 79.1584 | K9: =(JetFreight!J9/JetFreight!D9)^(1/6)-1 -> 0.067684882 | L9: =JetFreight!K127 -> 0.924891 | M9: =JetFreight!K129 -> 0.040392871 | N9: =JetFreight!K200 -> 0 | O9: =JetFreight!K199 -> 0.42824064 | P9: =JetFreight!K195 -> 0.19504924 | Q9: =JetFreight!K121 -> 0.020453399
A10: 6 | B10: Patel Integrated Logistics Ltd | C10: PATINTLOG | D10: 526381 | E10: Surface transport (Patel Roadways), domestic & international air-freight consolidation | F10: Asset-light carrier/consolidator | G10: =IF(P10>=MEDIAN($P$5:$P$14),"Asset-heavy","Asset-light") -> Asset-light | H10: =Patel!J9 -> 357.14 | I10: =Patel!J35 -> 163.32 | J10: =Patel!J69 -> 57.4896 | K10: =(Patel!J9/Patel!D9)^(1/6)-1 -> 0.0046143172 | L10: =Patel!K127 -> 0.90083674 | M10: =Patel!K129 -> 0.046566838 | N10: =Patel!K200 -> 0 | O10: =Patel!K199 -> 0.41678302 | P10: =Patel!K195 -> 0.28277252 | Q10: =Patel!K121 -> 0.0290875
A11: 7 | B11: Sical Logistics Ltd | C11: SICALLOG | D11: 520086 | E11: Bulk/mining logistics (coal), port & rail-road handling; IBC resolution plan of Pristine Malwa Logistics Park approved by NCLT Chennai (8-Dec-2022) | F11: Asset-heavy bulk logistics | G11: =IF(P11>=MEDIAN($P$5:$P$14),"Asset-heavy","Asset-light") -> Asset-heavy | H11: =Sical!J9 -> 385.68 | I11: =Sical!J35 -> 906.73 | J11: =Sical!J69 -> 502.69378 | K11: =(Sical!J9/Sical!D9)^(1/6)-1 -> -0.14765313 | L11: =Sical!K127 -> 0.77007687 | M11: =Sical!K129 -> 0.094975198 | N11: =Sical!K200 -> 0.0039427599 | O11: =Sical!K199 -> 0.088076785 | P11: =Sical!K195 -> 0.58793765 | Q11: =Sical!K121 -> 0.041720612
A12: 8 | B12: Transport Corporation of India Ltd | C12: TCI | D12: 532349 | E12: Integrated multimodal: road freight, supply-chain solutions/warehousing, coastal seaways, rail (JV with CONCOR) | F12: Hybrid multimodal | G12: =IF(P12>=MEDIAN($P$5:$P$14),"Asset-heavy","Asset-light") -> Asset-heavy | H12: =TCI!J9 -> 4916.77 | I12: =TCI!J35 -> 3481.86 | J12: =TCI!J69 -> 7079.41 | K12: =(TCI!J9/TCI!D9)^(1/6)-1 -> 0.10384815 | L12: =TCI!K127 -> 0.8143326 | M12: =TCI!K129 -> 0.054711809 | N12: =TCI!K200 -> 0.0036727148 | O12: =TCI!K199 -> 0.26417002 | P12: =TCI!K195 -> 0.39313615 | Q12: =TCI!K121 -> 0.10460636
A13: 9 | B13: Shreeji Translogistics Ltd | C13: — (BSE only) | D13: 540738 | E13: Road freight transport (full & part truck-load) and allied logistics | F13: Asset-light road carrier | G13: =IF(P13>=MEDIAN($P$5:$P$14),"Asset-heavy","Asset-light") -> Asset-light | H13: =Shreeji!J9 -> 234.29 | I13: =Shreeji!J35 -> 119.52 | J13: =Shreeji!J69 -> 41.1012 | K13: =(Shreeji!J9/Shreeji!D9)^(1/6)-1 -> 0.13429716 | L13: =Shreeji!K127 -> 0.80428674 | M13: =Shreeji!K129 -> 0.059367831 | N13: =Shreeji!K200 -> 0.025994572 | O13: =Shreeji!K199 -> 0.500792 | P13: =Shreeji!K195 -> 0.25601414 | Q13: =Shreeji!K121 -> 0.072103023
A14: 10 | B14: Mahindra Logistics Ltd | C14: MAHLOG | D14: 540768 | E14: Integrated 3PL: contract logistics & warehousing, B2B express, freight forwarding, last-mile, enterprise mobility | F14: Asset-light 3PL (leased) | G14: =IF(P14>=MEDIAN($P$5:$P$14),"Asset-heavy","Asset-light") -> Asset-light | H14: =MahindraLog!J9 -> 6999.3 | I14: =MahindraLog!J35 -> 3105.01 | J14: =MahindraLog!J69 -> 3301.376 | K14: =(MahindraLog!J9/MahindraLog!D9)^(1/6)-1 -> 0.12399336 | L14: =MahindraLog!K127 -> 0.85615338 | M14: =MahindraLog!K129 -> 0.07499944 | N14: =MahindraLog!K200 -> 0.0001263555 | O14: =MahindraLog!K199 -> 0.27364033 | P14: =MahindraLog!K195 -> 0.28888773 | Q14: =MahindraLog!K121 -> 0.046407247
B15: Median | H15: =MEDIAN(H5:H14) -> 1315.41 | I15: =MEDIAN(I5:I14) -> 1321.365 | J15: =MEDIAN(J5:J14) -> 789.05709 | K15: =MEDIAN(K5:K14) -> 0.085766516 | L15: =MEDIAN(L5:L14) -> 0.80930967 | M15: =MEDIAN(M5:M14) -> 0.057454646 | N15: =MEDIAN(N5:N14) -> 0.0017380706 | O15: =MEDIAN(O5:O14) -> 0.27182843 | ... Q15: =MEDIAN(Q5:Q14) -> 0.059255135
B16: Mean | H16: =AVERAGE(H5:H14) -> 3118.793 | I16: =AVERAGE(I5:I14) -> 2927.178 | J16: =AVERAGE(J5:J14) -> 5603.051 | K16: =AVERAGE(K5:K14) -> 0.038126002 | L16: =AVERAGE(L5:L14) -> 0.79623538 | M16: =AVERAGE(M5:M14) -> 0.077445173 | N16: =AVERAGE(N5:N14) -> 0.0049836364 | O16: =AVERAGE(O5:O14) -> 0.29979232 | ... Q16: =AVERAGE(Q5:Q14) -> 0.081391573
B17: Minimum | H17: =MIN(H5:H14) -> 234.29 | I17: =MIN(I5:I14) -> 119.52 | J17: =MIN(J5:J14) -> 41.1012 | K17: =MIN(K5:K14) -> -0.19109651 | L17: =MIN(L5:L14) -> 0.57413445 | M17: =MIN(M5:M14) -> 0.040392871 | N17: =MIN(N5:N14) -> 0 | O17: =MIN(O5:O14) -> 0.020044213 | ... Q17: =MIN(Q5:Q14) -> 0.020453399
B18: Maximum | H18: =MAX(H5:H14) -> 9078.97 | I18: =MAX(I5:I14) -> 15175.78 | J18: =MAX(J5:J14) -> 32390.848 | K18: =MAX(K5:K14) -> 0.13429716 | L18: =MAX(L5:L14) -> 0.924891 | M18: =MAX(M5:M14) -> 0.18587756 | N18: =MAX(N5:N14) -> 0.025994572 | O18: =MAX(O5:O14) -> 0.534418 | ... Q18: =MAX(Q5:Q14) -> 0.21971019
B19: Coeff. of variation (SD/mean) | H19: =STDEV(H5:H14)/AVERAGE(H5:H14) -> 1.0747906 | I19: =STDEV(I5:I14)/AVERAGE(I5:I14) -> 1.5588836 | J19: =STDEV(J5:J14)/AVERAGE(J5:J14) -> 1.8086734 | K19: =STDEV(K5:K14)/AVERAGE(K5:K14) -> 3.0540321 | L19: =STDEV(L5:L14)/AVERAGE(L5:L14) -> 0.14110106 | M19: =STDEV(M5:M14)/AVERAGE(M5:M14) -> 0.58854746 | N19: =STDEV(N5:N14)/AVERAGE(N5:N14) -> 1.671098 | O19: =STDEV(O5:O14)/AVERAGE(O5:O14) -> 0.56822631 | ... Q19: =STDEV(Q5:Q14)/AVERAGE(Q5:Q14) -> 0.82730417

Sheet Scorecard
A1: SCORECARD - key ratios vs industry (green = better than the 10-firm median, red = weaker)
A2: Block A: latest year FY2026. Block B: 7-year average FY2020-FY2026. Valuation ratios have no normative direction and are not coloured.
A4: Block A: FY2026
A5: Ratio | B5: Category | C5: Tiger | D5: Allcargo | E5: Blue Dart | F5: CONCOR | G5: Jet Freight | H5: Patel | I5: Sical | J5: TCI | K5: Shreeji | L5: Mahindra Log. | M5: Industry (agg.) | N5: Median
A6: Current ratio | B6: Liquidity | C6: =Tiger!J80 -> 4.6170581 | D6: =Allcargo!J80 -> 2.0255864 | E6: =BlueDart!J80 -> 1.3674138 | F6: =CONCOR!J80 -> 4.7511388 | G6: =JetFreight!J80 -> 3.5881855 | H6: =Patel!J80 -> 3.3649374 | I6: =Sical!J80 -> 1.1402597 | J6: =TCI!J80 -> 2.4182809 | K6: =Shreeji!J80 -> 4.7719752 | L6: =MahindraLog!J80 -> 1.4122438 | M6: =Industry!J80 -> 2.4360563 | N6: =IFERROR(MEDIAN(C6:L6),"N/M") -> 2.8916092
A7: Acid-test (quick) ratio | B7: Liquidity | C7: =Tiger!J81 -> 3.8983442 | D7: =Allcargo!J81 -> 1.1940299 | E7: =BlueDart!J81 -> 0.9578767 | F7: =CONCOR!J81 -> 3.1306054 | G7: =JetFreight!J81 -> 2.3645988 | H7: =Patel!J81 -> 2.9698867 | I7: =Sical!J81 -> 0.55759496 | J7: =TCI!J81 -> 1.5404411 | K7: =Shreeji!J81 -> 4.1773526 | L7: =MahindraLog!J81 -> 0.69438023 | M7: =Industry!J81 -> 1.5485939 | N7: =IFERROR(MEDIAN(C7:L7),"N/M") -> 1.9525199
A8: Cash flow from operations ratio | B8: Liquidity | C8: =Tiger!J84 -> -0.33923758 | D8: =Allcargo!J84 -> 0.66950959 | E8: =BlueDart!J84 -> 0.67067013 | F8: =CONCOR!J84 -> 1.1681588 | G8: =JetFreight!J84 -> -0.15350413 | H8: =Patel!J84 -> 0.23613596 | I8: =Sical!J84 -> 0.18013706 | J8: =TCI!J84 -> 0.7363912 | K8: =Shreeji!J84 -> 0.030506722 | L8: =MahindraLog!J84 -> 0.19805854 | M8: =Industry!J84 -> 0.63357276 | N8: =IFERROR(MEDIAN(C8:L8),"N/M") -> 0.21709725
A9: Debt-equity (Khan & Jain) | B9: Leverage | C9: =Tiger!J87 -> 0.31691461 | D9: =Allcargo!J87 -> 1.2073171 | E9: =BlueDart!J87 -> 0.64266137 | F9: =CONCOR!J87 -> 0.074528196 | G9: =JetFreight!J87 -> 1.0175848 | H9: =Patel!J87 -> 0.050680052 | I9: =Sical!J87 -> 3.6944931 | J9: =TCI!J87 -> 0.12174638 | K9: =Shreeji!J87 -> 0.66661121 | L9: =MahindraLog!J87 -> 0.55308228 | M9: =Industry!J87 -> 0.22560776 | N9: =IFERROR(MEDIAN(C9:L9),"N/M") -> 0.59787182
A10: Proprietary ratio | B10: Leverage | C10: =Tiger!J91 -> 0.60916914 | D10: =Allcargo!J91 -> 0.33064516 | E10: =BlueDart!J91 -> 0.43055357 | F10: =CONCOR!J91 -> 0.85282931 | G10: =JetFreight!J91 -> 0.3750322 | H10: =Patel!J91 -> 0.75630664 | I10: =Sical!J91 -> 0.14479503 | J10: =TCI!J91 -> 0.73695956 | K10: =Shreeji!J91 -> 0.50292838 | L10: =MahindraLog!J91 -> 0.37834983 | M10: =Industry!J91 -> 0.66895966 | N10: =IFERROR(MEDIAN(C10:L10),"N/M") -> 0.46674098
A11: Debt / EBITDA | B11: Leverage | C11: =Tiger!J93 -> 1.4334182 | D11: =Allcargo!J93 -> 2.5666667 | E11: =BlueDart!J93 -> 1.2039517 | F11: =CONCOR!J93 -> 0.41136031 | G11: =JetFreight!J93 -> 3.6131707 | H11: =Patel!J93 -> 0.47388342 | I11: =Sical!J93 -> 2.8398712 | J11: =TCI!J93 -> 0.48063017 | K11: =Shreeji!J93 -> 3.418942 | L11: =MahindraLog!J93 -> 1.6830721 | M11: =Industry!J93 -> 0.91070766 | N11: =IFERROR(MEDIAN(C11:L11),"N/M") -> 1.5582451
A12: Interest coverage | B12: Coverage | C12: =Tiger!J96 -> 6.5294118 | D12: =Allcargo!J96 -> 1.0645161 | E12: =BlueDart!J96 -> 4.81539 | F12: =CONCOR!J96 -> 22.020884 | G12: =JetFreight!J96 -> 2.6557143 | H12: =Patel!J96 -> 30.457143 | I12: =Sical!J96 -> 1.7926965 | J12: =TCI!J96 -> 22.93462 | K12: =Shreeji!J96 -> 1.8557692 | L12: =MahindraLog!J96 -> 1.4420155 | M12: =Industry!J96 -> 7.3623722 | N12: =IFERROR(MEDIAN(C12:L12),"N/M") -> 3.7355521
A13: Debt-service coverage ratio (DSCR) | B13: Coverage | C13: =Tiger!J102 -> 5.2656546 | D13: =Allcargo!J102 -> 1.8266667 | E13: =BlueDart!J102 -> 10.148295 | F13: =CONCOR!J102 -> 24.651216 | G13: =JetFreight!J102 -> 2.2442857 | H13: =Patel!J102 -> 1.7458101 | I13: =Sical!J102 -> 0.83683319 | J13: =TCI!J102 -> 26.605529 | K13: =Shreeji!J102 -> 2.0035398 | L13: =MahindraLog!J102 -> 1.2078898 | M13: =Industry!J102 -> 5.0193334 | N13: =IFERROR(MEDIAN(C13:L13),"N/M") -> 2.1239128
A14: Average collection period (days) | B14: Turnover | C14: =Tiger!J108 -> 84.017798 | D14: =Allcargo!J108 -> 71.297376 | E14: =BlueDart!J108 -> 50.651055 | F14: =CONCOR!J108 -> 17.788934 | G14: =JetFreight!J108 -> 71.984102 | H14: =Patel!J108 -> 71.627443 | I14: =Sical!J108 -> 79.53381 | J14: =TCI!J108 -> 57.098039 | K14: =Shreeji!J108 -> 105.5554 | L14: =MahindraLog!J108 -> 34.279274 | M14: =Industry!J108 -> 41.715692 | N14: =IFERROR(MEDIAN(C14:L14),"N/M") -> 71.46241
A15: Fixed assets turnover | B15: Turnover | C15: =Tiger!J112 -> 61.231427 | D15: =Allcargo!J112 -> 2.6692607 | E15: =BlueDart!J112 -> 3.1909295 | F15: =CONCOR!J112 -> 1.3204843 | G15: =JetFreight!J112 -> 17.507589 | H15: =Patel!J112 -> 7.6820822 | I15: =Sical!J112 -> 0.66643052 | J15: =TCI!J112 -> 4.5601862 | K15: =Shreeji!J112 -> 8.7064288 | L15: =MahindraLog!J112 -> 6.7397521 | M15: =Industry!J112 -> 2.5203355 | N15: =IFERROR(MEDIAN(C15:L15),"N/M") -> 5.6499692
A16: Total assets turnover | B16: Turnover | C16: =Tiger!J113 -> 2.4997054 | D16: =Allcargo!J113 -> 1.1837791 | E16: =BlueDart!J113 -> 1.5766848 | F16: =CONCOR!J113 -> 0.61234666 | G16: =JetFreight!J113 -> 2.3588654 | H16: =Patel!J113 -> 2.1550809 | I16: =Sical!J113 -> 0.43687275 | J16: =TCI!J113 -> 1.5326853 | K16: =Shreeji!J113 -> 1.9981237 | L16: =MahindraLog!J113 -> 2.4628902 | M16: =Industry!J113 -> 1.1101718 | N16: =IFERROR(MEDIAN(C16:L16),"N/M") -> 1.7874043
A17: Gross profit margin | B17: Profitability | C17: =Tiger!J119 -> 0.10107887 | D17: =Allcargo!J119 -> 0.26724976 | E17: =BlueDart!J119 -> 0.39087557 | F17: =CONCOR!J119 -> 0.33656461 | G17: =JetFreight!J119 -> 0.098856062 | H17: =Patel!J119 -> 0.092064737 | I17: =Sical!J119 -> 0.33465567 | J17: =TCI!J119 -> 0.18871739 | K17: =Shreeji!J119 -> 0.14328396 | L17: =MahindraLog!J119 -> 0.13752232 | M17: =Industry!J119 -> 0.26272151 | N17: =IFERROR(MEDIAN(C17:L17),"N/M") -> 0.16600068
A18: Operating EBITDA margin (core) | B18: Profitability | C18: =Tiger!J121 -> 0.047152683 | D18: =Allcargo!J121 -> 0.11418853 | E18: =BlueDart!J121 -> 0.15480843 | F18: =CONCOR!J121 -> 0.21492746 | G18: =JetFreight!J121 -> 0.037313097 | H18: =Patel!J121 -> 0.029036232 | I18: =Sical!J121 -> 0.2030699 | J18: =TCI!J121 -> 0.1055571 | K18: =Shreeji!J121 -> 0.033078663 | L18: =MahindraLog!J121 -> 0.054119698 | M18: =Industry!J121 -> 0.13385948 | N18: =IFERROR(MEDIAN(C18:L18),"N/M") -> 0.079838401
A19: Net profit margin | B19: Profitability | C19: =Tiger!J124 -> 0.037568521 | D19: =Allcargo!J124 -> 0.0038872692 | E19: =BlueDart!J124 -> 0.040285757 | F19: =CONCOR!J124 -> 0.13677763 | G19: =JetFreight!J124 -> 0.015312556 | H19: =Patel!J124 -> 0.026880215 | I19: =Sical!J124 -> 0.12777432 | J19: =TCI!J124 -> 0.09279466 | K19: =Shreeji!J124 -> 0.013487558 | L19: =MahindraLog!J124 -> 0.00032717557 | M19: =Industry!J124 -> 0.065605188 | N19: =IFERROR(MEDIAN(C19:L19),"N/M") -> 0.032224368
A20: Operating ratio | B20: Profitability | C20: =Tiger!J132 -> 0.95284732 | D20: =Allcargo!J132 -> 0.88581147 | E20: =BlueDart!J132 -> 0.84519157 | F20: =CONCOR!J132 -> 0.78507254 | G20: =JetFreight!J132 -> 0.9626869 | H20: =Patel!J132 -> 0.97096377 | I20: =Sical!J132 -> 0.7969301 | J20: =TCI!J132 -> 0.8944429 | K20: =Shreeji!J132 -> 0.96692134 | L20: =MahindraLog!J132 -> 0.9458803 | M20: =Industry!J132 -> 0.86614052 | N20: =IFERROR(MEDIAN(C20:L20),"N/M") -> 0.9201616
A21: Return on assets (ROA) | B21: Returns | C21: =Tiger!J135 -> 0.093910235 | D21: =Allcargo!J135 -> 0.0046016681 | E21: =BlueDart!J135 -> 0.063517942 | F21: =CONCOR!J135 -> 0.083755325 | G21: =JetFreight!J135 -> 0.036120259 | H21: =Patel!J135 -> 0.057929037 | I21: =Sical!J135 -> 0.055821119 | J21: =TCI!J135 -> 0.14222501 | K21: =Shreeji!J135 -> 0.02694981 | L21: =MahindraLog!J135 -> 0.00080579752 | M21: =Industry!J135 -> 0.072833032 | N21: =IFERROR(MEDIAN(C21:L21),"N/M") -> 0.056875078
A22: ROCE (post-tax) | B22: Returns | C22: =Tiger!J138 -> 0.13263629 | D22: =Allcargo!J138 -> 0.050574713 | E22: =BlueDart!J138 -> 0.11385367 | F22: =CONCOR!J138 -> 0.096133312 | G22: =JetFreight!J138 -> 0.078789833 | H22: =Patel!J138 -> 0.074973027 | I22: =Sical!J138 -> 0.18235018 | J22: =TCI!J138 -> 0.18230729 | K22: =Shreeji!J138 -> 0.069036714 | L22: =MahindraLog!J138 -> 0.022025614 | M22: =Industry!J138 -> 0.10374805 | N22: =IFERROR(MEDIAN(C22:L22),"N/M") -> 0.087461572
A23: Return on total shareholders' equity | B23: Returns | C23: =Tiger!J139 -> 0.14429395 | D23: =Allcargo!J139 -> 0.014084507 | E23: =BlueDart!J139 -> 0.14832113 | F23: =CONCOR!J139 -> 0.09807371 | G23: =JetFreight!J139 -> 0.097940372 | H23: =Patel!J139 -> 0.078309813 | I23: =Sical!J139 -> 0.77900727 | J23: =TCI!J139 -> 0.19329597 | K23: =Shreeji!J139 -> 0.054067927 | L23: =MahindraLog!J139 -> 0.0028400283 | M23: =Industry!J139 -> 0.11043587 | N23: =IFERROR(MEDIAN(C23:L23),"N/M") -> 0.098007041
A24: Price-earnings (P/E) | B24: Valuation | C24: =Tiger!J152 -> 11.738987 | D24: =Allcargo!J152 -> 134.42755 | E24: =BlueDart!J152 -> 45.476333 | F24: =CONCOR!J152 -> 26.083788 | G24: =JetFreight!J152 -> 11.640941 | H24: =Patel!J152 -> 5.9885 | I24: =Sical!J152 -> 10.200767 | J24: =TCI!J152 -> 15.516515 | K24: =Shreeji!J152 -> 13.006709 | L24: =MahindraLog!J152 -> 1441.6489 | M24: =Industry!J152 -> 27.384187 | N24: =IFERROR(MEDIAN(C24:L24),"N/M") -> 14.261612
A25: Price-to-book (P/B) | B25: Valuation | C25: =Tiger!J146 -> 1.5790911 | D25: =Allcargo!J146 -> 1.8735547 | E25: =BlueDart!J146 -> 6.33172 | F25: =CONCOR!J146 -> 2.5027022 | G25: =JetFreight!J146 -> 1.08749 | H25: =Patel!J146 -> 0.46542746 | I25: =Sical!J146 -> 3.828881 | J25: =TCI!J146 -> 2.758939 | K25: =Shreeji!J146 -> 0.68376643 | L25: =MahindraLog!J146 -> 2.8102079 | M25: =Industry!J146 -> 2.8613799 | N25: =IFERROR(MEDIAN(C25:L25),"N/M") -> 2.1881285
A26: Dividend yield | B26: Valuation | C26: =Tiger!J151 -> 0 | D26: =Allcargo!J151 -> 0 | E26: =BlueDart!J151 -> 0.005279817 | F26: =CONCOR!J151 -> 0.020221453 | G26: =JetFreight!J151 -> 0 | H26: =Patel!J151 -> 0.024178286 | I26: =Sical!J151 -> 0 | J26: =TCI!J151 -> 0.010841299 | K26: =Shreeji!J151 -> 0 | L26: =MahindraLog!J151 -> 0.0075120192 | M26: =Industry!J151 -> 0.014587231 | N26: =IFERROR(MEDIAN(C26:L26),"N/M") -> 0.0026399085
A27: EV / EBITDA | B27: Valuation | C27: =Tiger!J154 -> 7.4038168 | D27: =Allcargo!J154 -> 6.06452 | E27: =BlueDart!J154 -> 12.81373 | F27: =CONCOR!J154 -> 12.737852 | G27: =JetFreight!J154 -> 6.7638244 | H27: =Patel!J154 -> 2.7872521 | I27: =Sical!J154 -> 5.396802 | J27: =TCI!J154 -> 11.198129 | K27: =Shreeji!J154 -> 6.3806485 | L27: =MahindraLog!J154 -> 9.71785 | M27: =Industry!J154 -> 11.569531 | N27: =IFERROR(MEDIAN(C27:L27),"N/M") -> 7.0838206
A28: Total shareholder return (yield) | B28: Valuation | C28: =Tiger!J153 -> -0.49684211 | D28: =Allcargo!J153 -> -0.27911647 | E28: =BlueDart!J153 -> -0.22234771 | F28: =CONCOR!J153 -> -0.21576745 | G28: =JetFreight!J153 -> 0.48090278 | H28: =Patel!J153 -> -0.36678798 | I28: =Sical!J153 -> -0.079205027 | J28: =TCI!J153 -> -0.15373558 | K28: =Shreeji!J153 -> -0.33559322 | L28: =MahindraLog!J153 -> 0.40445673 | M28: =Industry!J153 -> n.a. | N28: =IFERROR(MEDIAN(C28:L28),"N/M") -> -0.21905758
A29: Internal growth rate | B29: Growth | C29: =Tiger!J170 -> 0.10364341 | D29: =Allcargo!J170 -> 0.0046229413 | E29: =BlueDart!J170 -> 0.050714697 | F29: =CONCOR!J170 -> 0.041209407 | G29: =JetFreight!J170 -> 0.037473823 | H29: =Patel!J170 -> 0.052123675 | I29: =Sical!J170 -> 0.059121338 | J29: =TCI!J170 -> 0.13417266 | K29: =Shreeji!J170 -> 0.027696218 | L29: =MahindraLog!J170 -> -0.0078584982 | M29: =Industry!J170 -> 0.045739811 | N29: =IFERROR(MEDIAN(C29:L29),"N/M") -> 0.045962052
A33: Block B: 7-yr average FY2020-26
A34: Ratio | B34: Category | C34: Tiger | D34: Allcargo | E34: Blue Dart | F34: CONCOR | G34: Jet Freight | H34: Patel | I34: Sical | J34: TCI | K34: Shreeji | L34: Mahindra Log. | M34: Industry (agg.) | N34: Median
A35: Current ratio | B35: Liquidity | C35: =Tiger!K80 -> 4.8832317 | D35: =Allcargo!K80 -> 1.6559883 | E35: =BlueDart!K80 -> 1.2083102 | F35: =CONCOR!K80 -> 3.9096987 | G35: =JetFreight!K80 -> 2.7399296 | H35: =Patel!K80 -> 5.5817034 | I35: =Sical!K80 -> 0.7195622 | J35: =TCI!K80 -> 2.8768546 | K35: =Shreeji!K80 -> 5.0975533 | L35: =MahindraLog!K80 -> 1.4129884 | M35: =Industry!K80 -> 1.9742087 | N35: =IFERROR(MEDIAN(C35:L35),"N/M") -> 2.8083921
A36: Acid-test (quick) ratio | B36: Liquidity | C36: =Tiger!K81 -> 4.1690597 | D36: =Allcargo!K81 -> 1.0636674 | E36: =BlueDart!K81 -> 0.82047016 | F36: =CONCOR!K81 -> 2.3952545 | G36: =JetFreight!K81 -> 1.620697 | H36: =Patel!K81 -> 4.3914109 | I36: =Sical!K81 -> 0.46681949 | J36: =TCI!K81 -> 1.9838517 | K36: =Shreeji!K81 -> 3.8810091 | L36: =MahindraLog!K81 -> 0.69863375 | M36: =Industry!K81 -> 1.2448907 | N36: =IFERROR(MEDIAN(C36:L36),"N/M") -> 1.8022743
A37: Cash flow from operations ratio | B37: Liquidity | C37: =Tiger!K84 -> 0.12295018 | D37: =Allcargo!K84 -> 0.33150185 | E37: =BlueDart!K84 -> 0.72776984 | F37: =CONCOR!K84 -> 1.2513667 | G37: =JetFreight!K84 -> -0.11414869 | H37: =Patel!K84 -> 0.10835287 | I37: =Sical!K84 -> 0.12059511 | J37: =TCI!K84 -> 0.99039578 | K37: =Shreeji!K84 -> 0.43081607 | L37: =MahindraLog!K84 -> 0.20161113 | M37: =Industry!K84 -> 0.55763214 | N37: =IFERROR(MEDIAN(C37:L37),"N/M") -> 0.26655649
A38: Debt-equity (Khan & Jain) | B38: Leverage | C38: =Tiger!K87 -> 0.24661787 | D38: =Allcargo!K87 -> 0.87612163 | E38: =BlueDart!K87 -> 1.1280755 | F38: =CONCOR!K87 -> 0.062736366 | G38: =JetFreight!K87 -> 1.3550845 | H38: =Patel!K87 -> 0.29634174 | I38: =Sical!K87 -> 8.2478837 | J38: =TCI!K87 -> 0.15977623 | K38: =Shreeji!K87 -> 1.2179689 | L38: =MahindraLog!K87 -> 1.0148062 | M38: =Industry!K87 -> 0.30963722 | N38: =IFERROR(MEDIAN(C38:L38),"N/M") -> 0.94546393
A39: Proprietary ratio | B39: Leverage | C39: =Tiger!K91 -> 0.64580193 | D39: =Allcargo!K91 -> 0.34869893 | E39: =BlueDart!K91 -> 0.33080972 | F39: =CONCOR!K91 -> 0.84060615 | G39: =JetFreight!K91 -> 0.30649204 | H39: =Patel!K91 -> 0.66174853 | I39: =Sical!K91 -> -0.079794883 | J39: =TCI!K91 -> 0.73518162 | K39: =Shreeji!K91 -> 0.4032542 | L39: =MahindraLog!K91 -> 0.28048555 | M39: =Industry!K91 -> 0.58700064 | N39: =IFERROR(MEDIAN(C39:L39),"N/M") -> 0.37597656
A40: Debt / EBITDA | B40: Leverage | C40: =Tiger!K93 -> 0.58256733 | D40: =Allcargo!K93 -> 2.3575529 | E40: =BlueDart!K93 -> 1.314398 | F40: =CONCOR!K93 -> 0.36006765 | G40: =JetFreight!K93 -> 4.8279833 | H40: =Patel!K93 -> 2.7982777 | I40: =Sical!K93 -> 54.774084 | J40: =TCI!K93 -> 0.59853111 | K40: =Shreeji!K93 -> 3.4213455 | L40: =MahindraLog!K93 -> 2.2238123 | M40: =Industry!K93 -> 1.4224331 | N40: =IFERROR(MEDIAN(C40:L40),"N/M") -> 2.2906826
A41: Interest coverage | B41: Coverage | C41: =Tiger!K96 -> 13.264266 | D41: =Allcargo!K96 -> 5.2576089 | E41: =BlueDart!K96 -> 4.9257002 | F41: =CONCOR!K96 -> 21.182849 | G41: =JetFreight!K96 -> 1.4276612 | H41: =Patel!K96 -> 6.9019376 | I41: =Sical!K96 -> -8.4085999 | J41: =TCI!K96 -> 22.136806 | K41: =Shreeji!K96 -> 2.7932856 | L41: =MahindraLog!K96 -> 2.1526989 | M41: =Industry!K96 -> 6.709308 | N41: =IFERROR(MEDIAN(C41:L41),"N/M") -> 5.0916545
A42: Debt-service coverage ratio (DSCR) | B42: Coverage | C42: =Tiger!K102 -> 8.3102234 | D42: =Allcargo!K102 -> 4.6259727 | E42: =BlueDart!K102 -> 6.3752773 | F42: =CONCOR!K102 -> 20.885259 | G42: =JetFreight!K102 -> 1.3408533 | H42: =Patel!K102 -> 1.0281497 | I42: =Sical!K102 -> -1.5379693 | J42: =TCI!K102 -> 18.499634 | K42: =Shreeji!K102 -> 2.809745 | L42: =MahindraLog!K102 -> 4.6701835 | M42: =Industry!K102 -> 3.5858462 | N42: =IFERROR(MEDIAN(C42:L42),"N/M") -> 4.6480781
A43: Average collection period (days) | B43: Turnover | C43: =Tiger!K108 -> 76.455526 | D43: =Allcargo!K108 -> 83.618072 | E43: =BlueDart!K108 -> 49.630432 | F43: =CONCOR!K108 -> 11.14588 | G43: =JetFreight!K108 -> 53.795498 | H43: =Patel!K108 -> 99.004829 | I43: =Sical!K108 -> 116.20477 | J43: =TCI!K108 -> 57.785641 | K43: =Shreeji!K108 -> 98.188972 | L43: =MahindraLog!K108 -> 44.989336 | M43: =Industry!K108 -> 45.713795 | N43: =IFERROR(MEDIAN(C43:L43),"N/M") -> 67.120583
A44: Fixed assets turnover | B44: Turnover | C44: =Tiger!K112 -> 47.069011 | D44: =Allcargo!K112 -> 4.1918699 | E44: =BlueDart!K112 -> 2.9788976 | F44: =CONCOR!K112 -> 1.355579 | G44: =JetFreight!K112 -> 16.059752 | H44: =Patel!K112 -> 5.7184543 | I44: =Sical!K112 -> 0.58461596 | J44: =TCI!K112 -> 4.3345309 | K44: =Shreeji!K112 -> 7.2256921 | L44: =MahindraLog!K112 -> 10.22712 | M44: =Industry!K112 -> 2.7828711 | N44: =IFERROR(MEDIAN(C44:L44),"N/M") -> 5.0264926
...

Sheet Industry_Compare
A1: INDUSTRY COMPARISON - every ratio, every firm, FY2020-FY2026
A2: Industry (aggregate) = ratio computed on summed financials of the 10 firms (size-weighted). Mean / Median / SD = simple statistics of the 10 firm ratios (N/M, N/C ignored). Assessment uses the median as the typical-firm benchmark.
A4: Firm / statistic | B4: FY2020 | C4: FY2021 | D4: FY2022 | E4: FY2023 | F4: FY2024 | G4: FY2025 | H4: FY2026 | I4: 7-yr avg | J4: FY26 vs median | K4: Assessment FY26 | L4: Rank FY26 (1 = best) | M4: 7-yr avg vs median | N4: Assessment 7-yr
A6: Net working capital (Rs cr) [CA - CL] - Liquidity; higher is better
A7: Tiger | B7: =Tiger!D79 -> 79.44 | C7: =Tiger!E79 -> 48.16 | D7: =Tiger!F79 -> 61.36 | E7: =Tiger!G79 -> 84.64 | F7: =Tiger!H79 -> 102.6 | G7: =Tiger!I79 -> 151.77 | H7: =Tiger!J79 -> 187.87 | I7: =Tiger!K79 -> 102.26286 | J7: =IF(AND(ISNUMBER(H7),ISNUMBER(H$19)),IF(H7>H$19,"Above",IF(H7<H$19,"Below","At")),"-") -> Below | K7: =IF(J7="Above","Better",IF(J7="Below","Weaker","-")) -> Weaker | L7: =IF(ISNUMBER(H7),RANK(H7,H$7:H$16,0),"-") -> 6 | N7: =IF(AND(ISNUMBER(I7),ISNUMBER(I$19)),IF(I7>I$19,"Above",IF(I7<I$19,"Below","At")),"-") -> Below | O7: =IF(N7="Above","Better",IF(N7="Below","Weaker","-")) -> Weaker
A8: Allcargo | B8: =Allcargo!D79 -> 1002.04 | C8: =Allcargo!E79 -> 857.7 | D8: =Allcargo!F79 -> 1417.79 | E8: =Allcargo!G79 -> 1265.14 | F8: =Allcargo!H79 -> 1242.73 | G8: =Allcargo!I79 -> 578 | H8: =Allcargo!J79 -> 481 | I8: =Allcargo!K79 -> 977.77143 | J8: =IF(AND(ISNUMBER(H8),ISNUMBER(H$19)),IF(H8>H$19,"Above",IF(H8<H$19,"Below","At")),"-") -> Above | K8: =IF(J8="Above","Better",IF(J8="Below","Weaker","-")) -> Better | L8: =IF(ISNUMBER(H8),RANK(H8,H$7:H$16,0),"-") -> 4 | N8: =IF(AND(ISNUMBER(I8),ISNUMBER(I$19)),IF(I8>I$19,"Above",IF(I8<I$19,"Below","At")),"-") -> Above | O8: =IF(N8="Above","Better",IF(N8="Below","Weaker","-")) -> Better
A9: Blue Dart | B9: =BlueDart!D79 -> -662.18 | C9: =BlueDart!E79 -> 374.18 | D9: =BlueDart!F79 -> 224.54 | E9: =BlueDart!G79 -> 252.87 | F9: =BlueDart!H79 -> 236.54 | G9: =BlueDart!I79 -> 289.72 | H9: =BlueDart!J79 -> 443.88 | I9: =BlueDart!K79 -> 165.65 | J9: =IF(AND(ISNUMBER(H9),ISNUMBER(H$19)),IF(H9>H$19,"Above",IF(H9<H$19,"Below","At")),"-") -> Above | K9: =IF(J9="Above","Better",IF(J9="Below","Weaker","-")) -> Better | L9: =IF(ISNUMBER(H9),RANK(H9,H$7:H$16,0),"-") -> 5 | N9: =IF(AND(ISNUMBER(I9),ISNUMBER(I$19)),IF(I9>I$19,"Above",IF(I9<I$19,"Below","At")),"-") -> Above | O9: =IF(N9="Above","Better",IF(N9="Below","Weaker","-")) -> Better
A10: CONCOR | B10: =CONCOR!D79 -> 2626.3 | C10: =CONCOR!E79 -> 3063.63 | D10: =CONCOR!F79 -> 3805.64 | E10: =CONCOR!G79 -> 4333.98 | F10: =CONCOR!H79 -> 4747.44 | G10: =CONCOR!I79 -> 4689.41 | H10: =CONCOR!J79 -> 4759.67 | I10: =CONCOR!K79 -> 4003.7243 | J10: =IF(AND(ISNUMBER(H10),ISNUMBER(H$19)),IF(H10>H$19,"Above",IF(H10<H$19,"Below","At")),"-") -> Above | K10: =IF(J10="Above","Better",IF(J10="Below","Weaker","-")) -> Better | L10: =IF(ISNUMBER(H10),RANK(H10,H$7:H$16,0),"-") -> 1 | N10: =IF(AND(ISNUMBER(I10),ISNUMBER(I$19)),IF(I10>I$19,"Above",IF(I10<I$19,"Below","At")),"-") -> Above | O10: =IF(N10="Above","Better",IF(N10="Below","Weaker","-")) -> Better
A11: Jet Freight | B11: =JetFreight!D79 -> 39.16 | C11: =JetFreight!E79 -> 23.78 | D11: =JetFreight!F79 -> 42.17 | E11: =JetFreight!G79 -> 92.29 | F11: =JetFreight!H79 -> 90.86 | G11: =JetFreight!I79 -> 103.78 | H11: =JetFreight!J79 -> 122.24 | I11: =JetFreight!K79 -> 73.468571 | J11: =IF(AND(ISNUMBER(H11),ISNUMBER(H$19)),IF(H11>H$19,"Above",IF(H11<H$19,"Below","At")),"-") -> Below | K11: =IF(J11="Above","Better",IF(J11="Below","Weaker","-")) -> Weaker | L11: =IF(ISNUMBER(H11),RANK(H11,H$7:H$16,0),"-") -> 7 | N11: =IF(AND(ISNUMBER(I11),ISNUMBER(I$19)),IF(I11>I$19,"Above",IF(I11<I$19,"Below","At")),"-") -> Below | O11: =IF(N11="Above","Better",IF(N11="Below","Weaker","-")) -> Weaker
A12: Patel | B12: =Patel!D79 -> 115.87 | C12: =Patel!E79 -> 115.04 | D12: =Patel!F79 -> 102.28 | E12: =Patel!G79 -> 88.52 | F12: =Patel!H79 -> 90.18 | G12: =Patel!I79 -> 83.19 | H12: =Patel!J79 -> 79.32 | I12: =Patel!K79 -> 96.342857 | J12: =IF(AND(ISNUMBER(H12),ISNUMBER(H$19)),IF(H12>H$19,"Above",IF(H12<H$19,"Below","At")),"-") -> Below | K12: =IF(J12="Above","Better",IF(J12="Below","Weaker","-")) -> Weaker | L12: =IF(ISNUMBER(H12),RANK(H12,H$7:H$16,0),"-") -> 8 | N12: =IF(AND(ISNUMBER(I12),ISNUMBER(I$19)),IF(I12>I$19,"Above",IF(I12<I$19,"Below","At")),"-") -> Below | O12: =IF(N12="Above","Better",IF(N12="Below","Weaker","-")) -> Weaker
A13: Sical | B13: =Sical!D79 -> -459.35 | C13: =Sical!E79 -> -646.28 | D13: =Sical!F79 -> -337.55 | E13: =Sical!G79 -> -68.93 | F13: =Sical!H79 -> -32.09 | G13: =Sical!I79 -> -51.8 | H13: =Sical!J79 -> 40.73 | I13: =Sical!K79 -> -222.18143 | J13: =IF(AND(ISNUMBER(H13),ISNUMBER(H$19)),IF(H13>H$19,"Above",IF(H13<H$19,"Below","At")),"-") -> Below | K13: =IF(J13="Above","Better",IF(J13="Below","Weaker","-")) -> Weaker | L13: =IF(ISNUMBER(H13),RANK(H13,H$7:H$16,0),"-") -> 10 | N13: =IF(AND(ISNUMBER(I13),ISNUMBER(I$19)),IF(I13>I$19,"Above",IF(I13<I$19,"Below","At")),"-") -> Below | O13: =IF(N13="Above","Better",IF(N13="Below","Weaker","-")) -> Weaker
A14: TCI | B14: =TCI!D79 -> 517.29 | C14: =TCI!E79 -> 507.36 | D14: =TCI!F79 -> 525.15 | E14: =TCI!G79 -> 690.52 | F14: =TCI!H79 -> 684.09 | G14: =TCI!I79 -> 766.74 | H14: =TCI!J79 -> 855.89 | I14: =TCI!K79 -> 649.57714 | J14: =IF(AND(ISNUMBER(H14),ISNUMBER(H$19)),IF(H14>H$19,"Above",IF(H14<H$19,"Below","At")),"-") -> Above | K14: =IF(J14="Above","Better",IF(J14="Below","Weaker","-")) -> Better | L14: =IF(ISNUMBER(H14),RANK(H14,H$7:H$16,0),"-") -> 2 | N14: =IF(AND(ISNUMBER(I14),ISNUMBER(I$19)),IF(I14>I$19,"Above",IF(I14<I$19,"Below","At")),"-") -> Above | O14: =IF(N14="Above","Better",IF(N14="Below","Weaker","-")) -> Better
A15: Shreeji | B15: =Shreeji!D79 -> 43.83 | C15: =Shreeji!E79 -> 46.23 | D15: =Shreeji!F79 -> 56.35 | E15: =Shreeji!G79 -> 56.1 | F15: =Shreeji!H79 -> 66.91 | G15: =Shreeji!I79 -> 65.55 | H15: =Shreeji!J79 -> 72.95 | I15: =Shreeji!K79 -> 58.274286 | J15: =IF(AND(ISNUMBER(H15),ISNUMBER(H$19)),IF(H15>H$19,"Above",IF(H15<H$19,"Below","At")),"-") -> Below | K15: =IF(J15="Above","Better",IF(J15="Below","Weaker","-")) -> Weaker | L15: =IF(ISNUMBER(H15),RANK(H15,H$7:H$16,0),"-") -> 9 | N15: =IF(AND(ISNUMBER(I15),ISNUMBER(I$19)),IF(I15>I$19,"Above",IF(I15<I$19,"Below","At")),"-") -> Below | O15: =IF(N15="Above","Better",IF(N15="Below","Weaker","-")) -> Weaker
A16: Mahindra Log. | B16: =MahindraLog!D79 -> 496.81 | C16: =MahindraLog!E79 -> 418.69 | D16: =MahindraLog!F79 -> 316.78 | E16: =MahindraLog!G79 -> 462.39 | F16: =MahindraLog!H79 -> 373.47 | G16: =MahindraLog!I79 -> 308.71 | H16: =MahindraLog!J79 -> 527.87 | I16: =MahindraLog!K79 -> 414.96 | J16: =IF(AND(ISNUMBER(H16),ISNUMBER(H$19)),IF(H16>H$19,"Above",IF(H16<H$19,"Below","At")),"-") -> Above | K16: =IF(J16="Above","Better",IF(J16="Below","Weaker","-")) -> Better | L16: =IF(ISNUMBER(H16),RANK(H16,H$7:H$16,0),"-") -> 3 | N16: =IF(AND(ISNUMBER(I16),ISNUMBER(I$19)),IF(I16>I$19,"Above",IF(I16<I$19,"Below","At")),"-") -> Above | O16: =IF(N16="Above","Better",IF(N16="Below","Weaker","-")) -> Better
A17: Industry (aggregate) | B17: =Industry!D79 -> 3799.21 | C17: =Industry!E79 -> 4808.49 | D17: =Industry!F79 -> 6214.51 | E17: =Industry!G79 -> 7257.52 | F17: =Industry!H79 -> 7602.73 | G17: =Industry!I79 -> 6985.07 | H17: =Industry!J79 -> 7571.42 | I17: =Industry!K79 -> 6319.85
A18: Mean (10 firms) | B18: =IFERROR(AVERAGE(B7:B16),"N/M") -> 379.921 | C18: =IFERROR(AVERAGE(C7:C16),"N/M") -> 480.849 | D18: =IFERROR(AVERAGE(D7:D16),"N/M") -> 621.451 | E18: =IFERROR(AVERAGE(E7:E16),"N/M") -> 725.752 | F18: =IFERROR(AVERAGE(F7:F16),"N/M") -> 760.273 | G18: =IFERROR(AVERAGE(G7:G16),"N/M") -> 698.507 | H18: =IFERROR(AVERAGE(H7:H16),"N/M") -> 757.142 | I18: =IFERROR(AVERAGE(I7:I16),"N/M") -> 631.985
A19: Median (10 firms) | B19: =IFERROR(MEDIAN(B7:B16),"N/M") -> 97.655 | C19: =IFERROR(MEDIAN(C7:C16),"N/M") -> 244.61 | D19: =IFERROR(MEDIAN(D7:D16),"N/M") -> 163.41 | E19: =IFERROR(MEDIAN(E7:E16),"N/M") -> 172.58 | F19: =IFERROR(MEDIAN(F7:F16),"N/M") -> 169.57 | G19: =IFERROR(MEDIAN(G7:G16),"N/M") -> 220.745 | H19: =IFERROR(MEDIAN(H7:H16),"N/M") -> 315.875 | I19: =IFERROR(MEDIAN(I7:I16),"N/M") -> 133.95643
A20: Std. deviation | B20: =IFERROR(STDEV(B7:B16),"N/M") -> 921.66644 | C20: =IFERROR(STDEV(C7:C16),"N/M") -> 989.83617 | D20: =IFERROR(STDEV(D7:D16),"N/M") -> 1210.6326 | E20: =IFERROR(STDEV(E7:E16),"N/M") -> 1329.2765 | F20: =IFERROR(STDEV(F7:F16),"N/M") -> 1452.8992 | G20: =IFERROR(STDEV(G7:G16),"N/M") -> 1424.4049 | H20: =IFERROR(STDEV(H7:H16),"N/M") -> 1430.8084 | I20: =IFERROR(STDEV(I7:I16),"N/M") -> 1233.3907
A21: Minimum | B21: =IFERROR(MIN(B7:B16),"N/M") -> -662.18 | C21: =IFERROR(MIN(C7:C16),"N/M") -> -646.28 | D21: =IFERROR(MIN(D7:D16),"N/M") -> -337.55 | E21: =IFERROR(MIN(E7:E16),"N/M") -> -68.93 | F21: =IFERROR(MIN(F7:F16),"N/M") -> -32.09 | G21: =IFERROR(MIN(G7:G16),"N/M") -> -51.8 | H21: =IFERROR(MIN(H7:H16),"N/M") -> 40.73 | I21: =IFERROR(MIN(I7:I16),"N/M") -> -222.18143
A22: Maximum | B22: =IFERROR(MAX(B7:B16),"N/M") -> 2626.3 | C22: =IFERROR(MAX(C7:C16),"N/M") -> 3063.63 | D22: =IFERROR(MAX(D7:D16),"N/M") -> 3805.64 | E22: =IFERROR(MAX(E7:E16),"N/M") -> 4333.98 | F22: =IFERROR(MAX(F7:F16),"N/M") -> 4747.44 | G22: =IFERROR(MAX(G7:G16),"N/M") -> 4689.41 | H22: =IFERROR(MAX(H7:H16),"N/M") -> 4759.67 | I22: =IFERROR(MAX(I7:I16),"N/M") -> 4003.7243
A24: Current ratio [CA / CL] - Liquidity; higher is better
A25: Tiger | B25: =Tiger!D80 -> 6.047014 | C25: =Tiger!E80 -> 2.7896693 | D25: =Tiger!F80 -> 2.310551 | E25: =Tiger!G80 -> 4.8683729 | F25: =Tiger!H80 -> 5.9541284 | G25: =Tiger!I80 -> 7.5958279 | H25: =Tiger!J80 -> 4.6170581 | I25: =Tiger!K80 -> 4.8832317 | J25: =IF(AND(ISNUMBER(H25),ISNUMBER(H$37)),IF(H25>H$37,"Above",IF(H25<H$37,"Below","At")),"-") -> Above | K25: =IF(J25="Above","Better",IF(J25="Below","Weaker","-")) -> Better | L25: =IF(ISNUMBER(H25),RANK(H25,H$25:H$34,0),"-") -> 3 | N25: =IF(AND(ISNUMBER(I25),ISNUMBER(I$37)),IF(I25>I$37,"Above",IF(I25<I$37,"Below","At")),"-") -> Above | O25: =IF(N25="Above","Better",IF(N25="Below","Weaker","-")) -> Better
A26: Allcargo | B26: =Allcargo!D80 -> 1.6456859 | C26: =Allcargo!E80 -> 1.2893373 | D26: =Allcargo!F80 -> 1.3437125 | E26: =Allcargo!G80 -> 1.3908215 | F26: =Allcargo!H80 -> 1.4445132 | G26: =Allcargo!I80 -> 2.4522613 | H26: =Allcargo!J80 -> 2.0255864 | I26: =Allcargo!K80 -> 1.6559883 | J26: =IF(AND(ISNUMBER(H26),ISNUMBER(H$37)),IF(H26>H$37,"Above",IF(H26<H$37,"Below","At")),"-") -> Below | K26: =IF(J26="Above","Better",IF(J26="Below","Weaker","-")) -> Weaker | L26: =IF(ISNUMBER(H26),RANK(H26,H$25:H$34,0),"-") -> 7 | N26: =IF(AND(ISNUMBER(I26),ISNUMBER(I$37)),IF(I26>I$37,"Above",IF(I26<I$37,"Below","At")),"-") -> Below | O26: =IF(N26="Above","Better",IF(N26="Below","Weaker","-")) -> Weaker
A27: Blue Dart | B27: =BlueDart!D80 -> 0.59123682 | C27: =BlueDart!E80 -> 1.4776847 | D27: =BlueDart!F80 -> 1.2520571 | E27: =BlueDart!G80 -> 1.2738644 | F27: =BlueDart!H80 -> 1.2317475 | G27: =BlueDart!I80 -> 1.2641671 | H27: =BlueDart!J80 -> 1.3674138 | I27: =BlueDart!K80 -> 1.2083102 | J27: =IF(AND(ISNUMBER(H27),ISNUMBER(H$37)),IF(H27>H$37,"Above",IF(H27<H$37,"Below","At")),"-") -> Below | K27: =IF(J27="Above","Better",IF(J27="Below","Weaker","-")) -> Weaker | L27: =IF(ISNUMBER(H27),RANK(H27,H$25:H$34,0),"-") -> 9 | N27: =IF(AND(ISNUMBER(I27),ISNUMBER(I$37)),IF(I27>I$37,"Above",IF(I27<I$37,"Below","At")),"-") -> Below | O27: =IF(N27="Above","Better",IF(N27="Below","Weaker","-")) -> Weaker
A28: CONCOR | B28: =CONCOR!D80 -> 2.5701338 | C28: =CONCOR!E80 -> 3.042066 | D28: =CONCOR!F80 -> 3.5179069 | E28: =CONCOR!G80 -> 3.9676867 | F28: =CONCOR!H80 -> 4.7198355 | G28: =CONCOR!I80 -> 4.7991234 | H28: =CONCOR!J80 -> 4.7511388 | I28: =CONCOR!K80 -> 3.9096987 | J28: =IF(AND(ISNUMBER(H28),ISNUMBER(H$37)),IF(H28>H$37,"Above",IF(H28<H$37,"Below","At")),"-") -> Above | K28: =IF(J28="Above","Better",IF(J28="Below","Weaker","-")) -> Better | L28: =IF(ISNUMBER(H28),RANK(H28,H$25:H$34,0),"-") -> 2 | N28: =IF(AND(ISNUMBER(I28),ISNUMBER(I$37)),IF(I28>I$37,"Above",IF(I28<I$37,"Below","At")),"-") -> Above | O28: =IF(N28="Above","Better",IF(N28="Below","Weaker","-")) -> Better
A29: Jet Freight | B29: =JetFreight!D80 -> 2.1770364 | C29: =JetFreight!E80 -> 1.5218345 | D29: =JetFreight!F80 -> 2.1581983 | E29: =JetFreight!G80 -> 4.0013008 | F29: =JetFreight!H80 -> 2.7379495 | G29: =JetFreight!I80 -> 2.9950019 | H29: =JetFreight!J80 -> 3.5881855 | I29: =JetFreight!K80 -> 2.7399296 | J29: =IF(AND(ISNUMBER(H29),ISNUMBER(H$37)),IF(H29>H$37,"Above",IF(H29<H$37,"Below","At")),"-") -> Above | K29: =IF(J29="Above","Better",IF(J29="Below","Weaker","-")) -> Better | L29: =IF(ISNUMBER(H29),RANK(H29,H$25:H$34,0),"-") -> 4 | N29: =IF(AND(ISNUMBER(I29),ISNUMBER(I$37)),IF(I29>I$37,"Above",IF(I29<I$37,"Below","At")),"-") -> Below | O29: =IF(N29="Above","Better",IF(N29="Below","Weaker","-")) -> Weaker
A30: Patel | B30: =Patel!D80 -> 5.5191108 | C30: =Patel!E80 -> 10.618729 | D30: =Patel!F80 -> 8.4062274 | E30: =Patel!G80 -> 4.8155172 | F30: =Patel!H80 -> 2.8559374 | G30: =Patel!I80 -> 3.4914645 | H30: =Patel!J80 -> 3.3649374 | I30: =Patel!K80 -> 5.5817034 | J30: =IF(AND(ISNUMBER(H30),ISNUMBER(H$37)),IF(H30>H$37,"Above",IF(H30<H$37,"Below","At")),"-") -> Above | K30: =IF(J30="Above","Better",IF(J30="Below","Weaker","-")) -> Better | L30: =IF(ISNUMBER(H30),RANK(H30,H$25:H$34,0),"-") -> 5 | N30: =IF(AND(ISNUMBER(I30),ISNUMBER(I$37)),IF(I30>I$37,"Above",IF(I30<I$37,"Below","At")),"-") -> Above | O30: =IF(N30="Above","Better",IF(N30="Below","Weaker","-")) -> Better
A31: Sical | B31: =Sical!D80 -> 0.53880059 | C31: =Sical!E80 -> 0.43040965 | D31: =Sical!F80 -> 0.53771673 | E31: =Sical!G80 -> 0.73076322 | F31: =Sical!H80 -> 0.86142419 | G31: =Sical!I80 -> 0.79756136 | H31: =Sical!J80 -> 1.1402597 | I31: =Sical!K80 -> 0.7195622 | J31: =IF(AND(ISNUMBER(H31),ISNUMBER(H$37)),IF(H31>H$37,"Above",IF(H31<H$37,"Below","At")),"-") -> Below | K31: =IF(J31="Above","Better",IF(J31="Below","Weaker","-")) -> Weaker | L31: =IF(ISNUMBER(H31),RANK(H31,H$25:H$34,0),"-") -> 10 | N31: =IF(AND(ISNUMBER(I31),ISNUMBER(I$37)),IF(I31>I$37,"Above",IF(I31<I$37,"Below","At")),"-") -> Below | O31: =IF(N31="Above","Better",IF(N31="Below","Weaker","-")) -> Weaker
A32: TCI | B32: =TCI!D80 -> 3.1791642 | C32: =TCI!E80 -> 2.8679037 | D32: =TCI!F80 -> 2.7474711 | E32: =TCI!G80 -> 3.2474207 | F32: =TCI!H80 -> 3.2510365 | G32: =TCI!I80 -> 2.4267054 | H32: =TCI!J80 -> 2.4182809 | I32: =TCI!K80 -> 2.8768546 | J32: =IF(AND(ISNUMBER(H32),ISNUMBER(H$37)),IF(H32>H$37,"Above",IF(H32<H$37,"Below","At")),"-") -> Below | K32: =IF(J32="Above","Better",IF(J32="Below","Weaker","-")) -> Weaker | L32: =IF(ISNUMBER(H32),RANK(H32,H$25:H$34,0),"-") -> 6 | N32: =IF(AND(ISNUMBER(I32),ISNUMBER(I$37)),IF(I32>I$37,"Above",IF(I32<I$37,"Below","At")),"-") -> Above | O32: =IF(N32="Above","Better",IF(N32="Below","Weaker","-")) -> Better
A33: Shreeji | B33: =Shreeji!D80 -> 6.1143524 | C33: =Shreeji!E80 -> 5.4709865 | D33: =Shreeji!F80 -> 5.4686757 | E33: =Shreeji!G80 -> 4.1375839 | F33: =Shreeji!H80 -> 4.7823629 | G33: =Shreeji!I80 -> 4.9369369 | H33: =Shreeji!J80 -> 4.7719752 | I33: =Shreeji!K80 -> 5.0975533 | J33: =IF(AND(ISNUMBER(H33),ISNUMBER(H$37)),IF(H33>H$37,"Above",IF(H33<H$37,"Below","At")),"-") -> Above | K33: =IF(J33="Above","Better",IF(J33="Below","Weaker","-")) -> Better | L33: =IF(ISNUMBER(H33),RANK(H33,H$25:H$34,0),"-") -> 1 | N33: =IF(AND(ISNUMBER(I33),ISNUMBER(I$37)),IF(I33>I$37,"Above",IF(I33<I$37,"Below","At")),"-") -> Above | O33: =IF(N33="Above","Better",IF(N33="Below","Weaker","-")) -> Better
A34: Mahindra Log. | B34: =MahindraLog!D80 -> 1.7350456 | C34: =MahindraLog!E80 -> 1.4929302 | D34: =MahindraLog!F80 -> 1.30859 | E34: =MahindraLog!G80 -> 1.3995697 | F34: =MahindraLog!H80 -> 1.2998699 | G34: =MahindraLog!I80 -> 1.2426698 | H34: =MahindraLog!J80 -> 1.4122438 | I34: =MahindraLog!K80 -> 1.4129884 | J34: =IF(AND(ISNUMBER(H34),ISNUMBER(H$37)),IF(H34>H$37,"Above",IF(H34<H$37,"Below","At")),"-") -> Below | K34: =IF(J34="Above","Better",IF(J34="Below","Weaker","-")) -> Weaker | L34: =IF(ISNUMBER(H34),RANK(H34,H$25:H$34,0),"-") -> 8 | N34: =IF(AND(ISNUMBER(I34),ISNUMBER(I$37)),IF(I34>I$37,"Above",IF(I34<I$37,"Below","At")),"-") -> Below | O34: =IF(N34="Above","Better",IF(N34="Below","Weaker","-")) -> Weaker
A35: Industry (aggregate) | B35: =Industry!D80 -> 1.5556838 | C35: =Industry!E80 -> 1.6328318 | D35: =Industry!F80 -> 1.7147979 | E35: =Industry!G80 -> 1.9761212 | F35: =Industry!H80 -> 2.0841188 | G35: =Industry!I80 -> 2.4198509 | H35: =Industry!J80 -> 2.4360563 | I35: =Industry!K80 -> 1.9742087
A36: Mean (10 firms) | B36: =IFERROR(AVERAGE(B25:B34),"N/M") -> 3.011758 | C36: =IFERROR(AVERAGE(C25:C34),"N/M") -> 3.1001551 | D36: =IFERROR(AVERAGE(D25:D34),"N/M") -> 2.9051107 | E36: =IFERROR(AVERAGE(E25:E34),"N/M") -> 2.9832901 | F36: =IFERROR(AVERAGE(F25:F34),"N/M") -> 2.9138805 | G36: =IFERROR(AVERAGE(G25:G34),"N/M") -> 3.200172 | H36: =IFERROR(AVERAGE(H25:H34),"N/M") -> 2.945708 | I36: =IFERROR(AVERAGE(I25:I34),"N/M") -> 3.0085821
A37: Median (10 firms) | B37: =IFERROR(MEDIAN(B25:B34),"N/M") -> 2.3735851 | C37: =IFERROR(MEDIAN(C25:C34),"N/M") -> 2.1557519 | D37: =IFERROR(MEDIAN(D25:D34),"N/M") -> 2.2343747 | E37: =IFERROR(MEDIAN(E25:E34),"N/M") -> 3.6075537 | F37: =IFERROR(MEDIAN(F25:F34),"N/M") -> 2.7969435 | G37: =IFERROR(MEDIAN(G25:G34),"N/M") -> 2.7236316 | H37: =IFERROR(MEDIAN(H25:H34),"N/M") -> 2.8916092 | I37: =IFERROR(MEDIAN(I25:I34),"N/M") -> 2.8083921
A38: Std. deviation | B38: =IFERROR(STDEV(B25:B34),"N/M") -> 2.1477661 | C38: =IFERROR(STDEV(C25:C34),"N/M") -> 2.9891803 | D38: =IFERROR(STDEV(D25:D34),"N/M") -> 2.3914171 | E38: =IFERROR(STDEV(E25:E34),"N/M") -> 1.6110133 | F38: =IFERROR(STDEV(F25:F34),"N/M") -> 1.762259 | G38: =IFERROR(STDEV(G25:G34),"N/M") -> 2.0958113 | H38: =IFERROR(STDEV(H25:H34),"N/M") -> 1.460736 | I38: =IFERROR(STDEV(I25:I34),"N/M") -> 1.7718986
A39: Minimum | B39: =IFERROR(MIN(B25:B34),"N/M") -> 0.53880059 | C39: =IFERROR(MIN(C25:C34),"N/M") -> 0.43040965 | D39: =IFERROR(MIN(D25:D34),"N/M") -> 0.53771673 | E39: =IFERROR(MIN(E25:E34),"N/M") -> 0.73076322 | F39: =IFERROR(MIN(F25:F34),"N/M") -> 0.86142419 | G39: =IFERROR(MIN(G25:G34),"N/M") -> 0.79756136 | H39: =IFERROR(MIN(H25:H34),"N/M") -> 1.1402597 | I39: =IFERROR(MIN(I25:I34),"N/M") -> 0.7195622
A40: Maximum | B40: =IFERROR(MAX(B25:B34),"N/M") -> 6.1143524 | C40: =IFERROR(MAX(C25:C34),"N/M") -> 10.618729 | D40: =IFERROR(MAX(D25:D34),"N/M") -> 8.4062274 | E40: =IFERROR(MAX(E25:E34),"N/M") -> 4.8683729 | F40: =IFERROR(MAX(F25:F34),"N/M") -> 5.9541284 | G40: =IFERROR(MAX(G25:G34),"N/M") -> 7.5958279 | H40: =IFERROR(MAX(H25:H34),"N/M") -> 4.7719752 | I40: =IFERROR(MAX(I25:I34),"N/M") -> 5.5817034
A42: Acid-test (quick) ratio [(CA - Inventory - Prepaids) / CL = (Receivables + Cash) / CL] - Liquidity; higher is better
A43: Tiger | B43: =Tiger!D81 -> 4.5463787 | C43: =Tiger!E81 -> 1.8784838 | D43: =Tiger!F81 -> 2.1405382 | E43: =Tiger!G81 -> 4.6480804 | F43: =Tiger!H81 -> 5.385804 | G43: =Tiger!I81 -> 6.6857888 | H43: =Tiger!J81 -> 3.8983442 | I43: =Tiger!K81 -> 4.1690597 | J43: =IF(AND(ISNUMBER(H43),ISNUMBER(H$55)),IF(H43>H$55,"Above",IF(H43<H$55,"Below","At")),"-") -> Above | K43: =IF(J43="Above","Better",IF(J43="Below","Weaker","-")) -> Better | L43: =IF(ISNUMBER(H43),RANK(H43,H$43:H$52,0),"-") -> 2 | N43: =IF(AND(ISNUMBER(I43),ISNUMBER(I$55)),IF(I43>I$55,"Above",IF(I43<I$55,"Below","At")),"-") -> Above | O43: =IF(N43="Above","Better",IF(N43="Below","Weaker","-")) -> Better
A44: Allcargo | B44: =Allcargo!D81 -> 1.1198466 | C44: =Allcargo!E81 -> 0.86255381 | D44: =Allcargo!F81 -> 0.90198137 | E44: =Allcargo!G81 -> 1.0338819 | F44: =Allcargo!H81 -> 0.99669494 | G44: =Allcargo!I81 -> 1.3366834 | H44: =Allcargo!J81 -> 1.1940299 | I44: =Allcargo!K81 -> 1.0636674 | J44: =IF(AND(ISNUMBER(H44),ISNUMBER(H$55)),IF(H44>H$55,"Above",IF(H44<H$55,"Below","At")),"-") -> Below | K44: =IF(J44="Above","Better",IF(J44="Below","Weaker","-")) -> Weaker | L44: =IF(ISNUMBER(H44),RANK(H44,H$43:H$52,0),"-") -> 7 | N44: =IF(AND(ISNUMBER(I44),ISNUMBER(I$55)),IF(I44>I$55,"Above",IF(I44<I$55,"Below","At")),"-") -> Below | O44: =IF(N44="Above","Better",IF(N44="Below","Weaker","-")) -> Weaker
...

Sheet Statistics
A1: STATISTICAL ANALYSIS of the ratio panel (10 firms x 7 years, FY2020-FY2026)
A2: Descriptive statistics use all 70 firm-years. Inferential tests (B-F) use the 63 firm-years of 9 firms: Sical Logistics is excluded as an outlier (negative/near-zero net worth in 5 of 7 years under IBC resolution).
A4: A. DESCRIPTIVE STATISTICS - pooled panel
A5: Variable | B5: N | C5: Mean | D5: Median | E5: Std. dev. | F5: Coeff. of variation | G5: Minimum | H5: Maximum | I5: Skewness | J5: Kurtosis | K5: Mean ex-Sical | L5: Median ex-Sical
A6: Sales (Rs cr) | B6: =COUNT(Panel!$C$2:$C$71) -> 70 | C6: =AVERAGE(Panel!$C$2:$C$71) -> 3331.3929 | D6: =MEDIAN(Panel!$C$2:$C$71) -> 1483.42 | E6: =STDEV(Panel!$C$2:$C$71) -> 4086.3364 | F6: =IFERROR(E6/ABS(C6),"N/M") -> 1.226615 | G6: =MIN(Panel!$C$2:$C$71) -> 108.23 | H6: =MAX(Panel!$C$2:$C$71) -> 19062.06 | I6: =SKEW(Panel!$C$2:$C$71) -> 1.8313391 | J6: =KURT(Panel!$C$2:$C$71) -> 4.0593186 | K6: =AVERAGE(Panel!$C$2:$C$64) -> 3652.674 | L6: =MEDIAN(Panel!$C$2:$C$64) -> 2802.39
A7: Total assets (Rs cr) | B7: =COUNT(Panel!$D$2:$D$71) -> 70 | C7: =AVERAGE(Panel!$D$2:$D$71) -> 2896.4641 | D7: =MEDIAN(Panel!$D$2:$D$71) -> 1685.125 | E7: =STDEV(Panel!$D$2:$D$71) -> 4078.1112 | F7: =IFERROR(E7/ABS(C7),"N/M") -> 1.4079619 | G7: =MIN(Panel!$D$2:$D$71) -> 79.35 | H7: =MAX(Panel!$D$2:$D$71) -> 15175.78 | I7: =SKEW(Panel!$D$2:$D$71) -> 1.8675486 | J7: =KURT(Panel!$D$2:$D$71) -> 2.4846677 | K7: =AVERAGE(Panel!$D$2:$D$64) -> 3069.2495 | L7: =MEDIAN(Panel!$D$2:$D$64) -> 1736
A8: Net block | B8: =COUNT(Panel!$E$2:$E$71) -> 70 | C8: =AVERAGE(Panel!$E$2:$E$71) -> 0.34297414 | D8: =MEDIAN(Panel!$E$2:$E$71) -> 0.33863637 | E8: =STDEV(Panel!$E$2:$E$71) -> 0.16287551 | F8: =IFERROR(E8/ABS(C8),"N/M") -> 0.47489152 | G8: =MIN(Panel!$E$2:$E$71) -> 0.03739243 | H8: =MAX(Panel!$E$2:$E$71) -> 0.76336994 | I8: =SKEW(Panel!$E$2:$E$71) -> 0.22437037 | J8: =KURT(Panel!$E$2:$E$71) -> 0.0070443888 | K8: =AVERAGE(Panel!$E$2:$E$64) -> 0.31575597 | L8: =MEDIAN(Panel!$E$2:$E$64) -> 0.32499001
A9: Current ratio | B9: =COUNT(Panel!$F$2:$F$71) -> 70 | C9: =AVERAGE(Panel!$F$2:$F$71) -> 3.0085821 | D9: =MEDIAN(Panel!$F$2:$F$71) -> 2.6540417 | E9: =STDEV(Panel!$F$2:$F$71) -> 2.0292796 | F9: =IFERROR(E9/ABS(C9),"N/M") -> 0.67449701 | G9: =MIN(Panel!$F$2:$F$71) -> 0.43040965 | H9: =MAX(Panel!$F$2:$F$71) -> 10.618729 | I9: =SKEW(Panel!$F$2:$F$71) -> 1.2360351 | J9: =KURT(Panel!$F$2:$F$71) -> 1.9761816 | K9: =AVERAGE(Panel!$F$2:$F$64) -> 3.2629176 | L9: =MEDIAN(Panel!$F$2:$F$64) -> 2.8559374
A10: Acid-test (quick) ratio | B10: =COUNT(Panel!$G$2:$G$71) -> 70 | C10: =AVERAGE(Panel!$G$2:$G$71) -> 2.1490874 | D10: =MEDIAN(Panel!$G$2:$G$71) -> 1.6964646 | E10: =STDEV(Panel!$G$2:$G$71) -> 1.6602266 | F10: =IFERROR(E10/ABS(C10),"N/M") -> 0.77252633 | G10: =MIN(Panel!$G$2:$G$71) -> 0.24450927 | H10: =MAX(Panel!$G$2:$G$71) -> 7.9423077 | I10: =SKEW(Panel!$G$2:$G$71) -> 1.2873811 | J10: =KURT(Panel!$G$2:$G$71) -> 1.5536181 | K10: =AVERAGE(Panel!$G$2:$G$64) -> 2.336006 | L10: =MEDIAN(Panel!$G$2:$G$64) -> 1.8784838
A11: Interest coverage | B11: =COUNT(Panel!$H$2:$H$71) -> 70 | C11: =AVERAGE(Panel!$H$2:$H$71) -> 7.1634213 | D11: =MEDIAN(Panel!$H$2:$H$71) -> 2.8436747 | E11: =STDEV(Panel!$H$2:$H$71) -> 12.060859 | F11: =IFERROR(E11/ABS(C11),"N/M") -> 1.683673 | G11: =MIN(Panel!$H$2:$H$71) -> -41.722767 | H11: =MAX(Panel!$H$2:$H$71) -> 38.070265 | I11: =SKEW(Panel!$H$2:$H$71) -> -0.11833648 | J11: =KURT(Panel!$H$2:$H$71) -> 3.3388255 | K11: =AVERAGE(Panel!$H$2:$H$64) -> 8.8936459 | L11: =MEDIAN(Panel!$H$2:$H$64) -> 4.6037736
A12: Average collection period (days) | B12: =COUNT(Panel!$I$2:$I$71) -> 70 | C12: =AVERAGE(Panel!$I$2:$I$71) -> 69.081895 | D12: =MEDIAN(Panel!$I$2:$I$71) -> 58.324266 | E12: =STDEV(Panel!$I$2:$I$71) -> 40.57288 | F12: =IFERROR(E12/ABS(C12),"N/M") -> 0.58731568 | G12: =MIN(Panel!$I$2:$I$71) -> 7.2692362 | H12: =MAX(Panel!$I$2:$I$71) -> 242.2178 | I12: =SKEW(Panel!$I$2:$I$71) -> 1.5277615 | J12: =KURT(Panel!$I$2:$I$71) -> 4.4609806 | K12: =AVERAGE(Panel!$I$2:$I$64) -> 63.846021 | L12: =MEDIAN(Panel!$I$2:$I$64) -> 57.098039
A13: Fixed assets turnover | B13: =COUNT(Panel!$J$2:$J$71) -> 70 | C13: =AVERAGE(Panel!$J$2:$J$71) -> 9.9745523 | D13: =MEDIAN(Panel!$J$2:$J$71) -> 4.8950623 | E13: =STDEV(Panel!$J$2:$J$71) -> 14.726542 | F13: =IFERROR(E13/ABS(C13),"N/M") -> 1.4764113 | G13: =MIN(Panel!$J$2:$J$71) -> 0.38032409 | H13: =MAX(Panel!$J$2:$J$71) -> 74.694596 | I13: =SKEW(Panel!$J$2:$J$71) -> 2.9548839 | J13: =KURT(Panel!$J$2:$J$71) -> 8.8785515 | K13: =AVERAGE(Panel!$J$2:$J$64) -> 11.017879 | L13: =MEDIAN(Panel!$J$2:$J$64) -> 5.6101564
A14: Net profit margin | B14: =COUNT(Panel!$K$2:$K$71) -> 70 | C14: =AVERAGE(Panel!$K$2:$K$71) -> -0.043119785 | D14: =MEDIAN(Panel!$K$2:$K$71) -> 0.024528847 | E14: =STDEV(Panel!$K$2:$K$71) -> 0.39058515 | F14: =IFERROR(E14/ABS(C14),"N/M") -> 9.0581423 | G14: =MIN(Panel!$K$2:$K$71) -> -2.3024443 | H14: =MAX(Panel!$K$2:$K$71) -> 0.14567552 | I14: =SKEW(Panel!$K$2:$K$71) -> -5.2218752 | J14: =KURT(Panel!$K$2:$K$71) -> 27.543751 | K14: =AVERAGE(Panel!$K$2:$K$64) -> 0.037783723 | L14: =MEDIAN(Panel!$K$2:$K$64) -> 0.030914481
A15: Return on assets (ROA) | B15: =COUNT(Panel!$L$2:$L$71) -> 70 | C15: =AVERAGE(Panel!$L$2:$L$71) -> 0.030509583 | D15: =MEDIAN(Panel!$L$2:$L$71) -> 0.036443292 | E15: =STDEV(Panel!$L$2:$L$71) -> 0.13543673 | F15: =IFERROR(E15/ABS(C15),"N/M") -> 4.4391538 | G15: =MIN(Panel!$L$2:$L$71) -> -0.70715131 | H15: =MAX(Panel!$L$2:$L$71) -> 0.32793759 | I15: =SKEW(Panel!$L$2:$L$71) -> -3.1955002 | J15: =KURT(Panel!$L$2:$L$71) -> 15.576852 | K15: =AVERAGE(Panel!$L$2:$L$64) -> 0.056625729 | L15: =MEDIAN(Panel!$L$2:$L$64) -> 0.041965016
A16: Return on total shareholders' equity | B16: =COUNT(Panel!$M$2:$M$71) -> 67 | C16: =AVERAGE(Panel!$M$2:$M$71) -> 0.06455921 | D16: =MEDIAN(Panel!$M$2:$M$71) -> 0.097940372 | E16: =STDEV(Panel!$M$2:$M$71) -> 0.34117068 | F16: =IFERROR(E16/ABS(C16),"N/M") -> 5.2846168 | G16: =MIN(Panel!$M$2:$M$71) -> -2.1569937 | H16: =MAX(Panel!$M$2:$M$71) -> 0.77900727 | I16: =SKEW(Panel!$M$2:$M$71) -> -4.2666836 | J16: =KURT(Panel!$M$2:$M$71) -> 27.663679 | K16: =AVERAGE(Panel!$M$2:$M$64) -> 0.10455704 | L16: =MEDIAN(Panel!$M$2:$M$64) -> 0.09807371
A17: Price-earnings (P/E) | B17: =COUNT(Panel!$N$2:$N$71) -> 51 | C17: =AVERAGE(Panel!$N$2:$N$71) -> 114.77776 | D17: =MEDIAN(Panel!$N$2:$N$71) -> 30.117025 | E17: =STDEV(Panel!$N$2:$N$71) -> 293.23105 | F17: =IFERROR(E17/ABS(C17),"N/M") -> 2.5547723 | G17: =MIN(Panel!$N$2:$N$71) -> 3.1335196 | H17: =MAX(Panel!$N$2:$N$71) -> 1441.6489 | I17: =SKEW(Panel!$N$2:$N$71) -> 3.8829253 | J17: =KURT(Panel!$N$2:$N$71) -> 14.622695 | K17: =AVERAGE(Panel!$N$2:$N$64) -> 116.8693 | L17: =MEDIAN(Panel!$N$2:$N$64) -> 31.390868
A18: Price-to-book (P/B) | B18: =COUNT(Panel!$O$2:$O$71) -> 61 | C18: =AVERAGE(Panel!$O$2:$O$71) -> 4.4933226 | D18: =MEDIAN(Panel!$O$2:$O$71) -> 2.9993067 | E18: =STDEV(Panel!$O$2:$O$71) -> 5.672244 | F18: =IFERROR(E18/ABS(C18),"N/M") -> 1.2623719 | G18: =MIN(Panel!$O$2:$O$71) -> 0.062998015 | H18: =MAX(Panel!$O$2:$O$71) -> 33.431025 | I18: =SKEW(Panel!$O$2:$O$71) -> 3.1105405 | J18: =KURT(Panel!$O$2:$O$71) -> 12.059266 | K18: =AVERAGE(Panel!$O$2:$O$64) -> 4.1401242 | L18: =MEDIAN(Panel!$O$2:$O$64) -> 2.9993067
A19: EV / EBITDA | B19: =COUNT(Panel!$P$2:$P$71) -> 58 | C19: =AVERAGE(Panel!$P$2:$P$71) -> 16.027757 | D19: =MEDIAN(Panel!$P$2:$P$71) -> 12.186766 | E19: =STDEV(Panel!$P$2:$P$71) -> 24.50013 | F19: =IFERROR(E19/ABS(C19),"N/M") -> 1.5286063 | G19: =MIN(Panel!$P$2:$P$71) -> 2.7872521 | H19: =MAX(Panel!$P$2:$P$71) -> 193.24634 | I19: =SKEW(Panel!$P$2:$P$71) -> 6.8664143 | J19: =KURT(Panel!$P$2:$P$71) -> 50.214892 | K19: =AVERAGE(Panel!$P$2:$P$64) -> 12.788114 | L19: =MEDIAN(Panel!$P$2:$P$64) -> 12.0664
A20: ROCE (post-tax) | B20: =COUNT(Panel!$Q$2:$Q$71) -> 70 | C20: =AVERAGE(Panel!$Q$2:$Q$71) -> 0.058908496 | D20: =MEDIAN(Panel!$Q$2:$Q$71) -> 0.07688143 | E20: =STDEV(Panel!$Q$2:$Q$71) -> 0.21531167 | F20: =IFERROR(E20/ABS(C20),"N/M") -> 3.655019 | G20: =MIN(Panel!$Q$2:$Q$71) -> -1.1777556 | H20: =MAX(Panel!$Q$2:$Q$71) -> 0.53267131 | I20: =SKEW(Panel!$Q$2:$Q$71) -> -3.8918335 | J20: =KURT(Panel!$Q$2:$Q$71) -> 20.097013 | K20: =AVERAGE(Panel!$Q$2:$Q$64) -> 0.099997594 | L20: =MEDIAN(Panel!$Q$2:$Q$64) -> 0.088036094
A21: Total assets turnover | B21: =COUNT(Panel!$R$2:$R$71) -> 70 | C21: =AVERAGE(Panel!$R$2:$R$71) -> 1.7640934 | D21: =MEDIAN(Panel!$R$2:$R$71) -> 1.6869021 | E21: =STDEV(Panel!$R$2:$R$71) -> 1.0265913 | F21: =IFERROR(E21/ABS(C21),"N/M") -> 0.58193707 | G21: =MIN(Panel!$R$2:$R$71) -> 0.21165186 | H21: =MAX(Panel!$R$2:$R$71) -> 5.9981472 | I21: =SKEW(Panel!$R$2:$R$71) -> 1.1592733 | J21: =KURT(Panel!$R$2:$R$71) -> 3.4164363 | K21: =AVERAGE(Panel!$R$2:$R$64) -> 1.9263613 | L21: =MEDIAN(Panel!$R$2:$R$64) -> 1.8019151
A22: Operating EBITDA margin (core) | B22: =COUNT(Panel!$S$2:$S$71) -> 70 | C22: =AVERAGE(Panel!$S$2:$S$71) -> 0.081391573 | D22: =MEDIAN(Panel!$S$2:$S$71) -> 0.0635277 | E22: =STDEV(Panel!$S$2:$S$71) -> 0.074728009 | F22: =IFERROR(E22/ABS(C22),"N/M") -> 0.91812956 | G22: =MIN(Panel!$S$2:$S$71) -> -0.11224812 | H22: =MAX(Panel!$S$2:$S$71) -> 0.25944103 | I22: =SKEW(Panel!$S$2:$S$71) -> 0.47722233 | J22: =KURT(Panel!$S$2:$S$71) -> 0.20484275 | K22: =AVERAGE(Panel!$S$2:$S$64) -> 0.085799457 | L22: =MEDIAN(Panel!$S$2:$S$64) -> 0.06316628
A23: Debt-equity (Khan & Jain) | B23: =COUNT(Panel!$T$2:$T$71) -> 67 | C23: =AVERAGE(Panel!$T$2:$T$71) -> 1.1566304 | D23: =MEDIAN(Panel!$T$2:$T$71) -> 0.66661121 | E23: =STDEV(Panel!$T$2:$T$71) -> 2.3997399 | F23: =IFERROR(E23/ABS(C23),"N/M") -> 2.0747682 | G23: =MIN(Panel!$T$2:$T$71) -> 0 | H23: =MAX(Panel!$T$2:$T$71) -> 17.661908 | I23: =SKEW(Panel!$T$2:$T$71) -> 5.6286252 | J23: =KURT(Panel!$T$2:$T$71) -> 35.960985 | K23: =AVERAGE(Panel!$T$2:$T$64) -> 0.70639211 | L23: =MEDIAN(Panel!$T$2:$T$64) -> 0.64266137
A25: B. CORRELATION MATRIX (Pearson) - 63 firm-years, 9 firms
B26: Current ratio | C26: Debt-equity (Khan & Ja | D26: Interest coverage | E26: Average collection per | F26: Total assets turnover | G26: Operating EBITDA margi | H26: Net profit margin | I26: ROCE (post-tax) | J26: Return on total shareh | K26: Net block
A27: Current ratio | B27: =CORREL(Panel!$F$2:$F$64,Panel!$F$2:$F$64) -> 1 | C27: =CORREL(Panel!$F$2:$F$64,Panel!$T$2:$T$64) -> -0.22485167 | D27: =CORREL(Panel!$F$2:$F$64,Panel!$H$2:$H$64) -> 0.080291347 | E27: =CORREL(Panel!$F$2:$F$64,Panel!$I$2:$I$64) -> 0.37172608 | F27: =CORREL(Panel!$F$2:$F$64,Panel!$R$2:$R$64) -> -0.12844468 | G27: =CORREL(Panel!$F$2:$F$64,Panel!$S$2:$S$64) -> -0.15873841 | H27: =CORREL(Panel!$F$2:$F$64,Panel!$K$2:$K$64) -> 0.07048714 | I27: =CORREL(Panel!$F$2:$F$64,Panel!$Q$2:$Q$64) -> -0.084995625 | J27: =CORREL(Panel!$F$2:$F$64,Panel!$M$2:$M$64) -> -0.082784283 | K27: =CORREL(Panel!$F$2:$F$64,Panel!$E$2:$E$64) -> -0.3946427
A28: Debt-equity (Khan & Jain) | B28: =CORREL(Panel!$T$2:$T$64,Panel!$F$2:$F$64) -> -0.22485167 | C28: =CORREL(Panel!$T$2:$T$64,Panel!$T$2:$T$64) -> 1 | D28: =CORREL(Panel!$T$2:$T$64,Panel!$H$2:$H$64) -> -0.63024213 | E28: =CORREL(Panel!$T$2:$T$64,Panel!$I$2:$I$64) -> 0.20230971 | F28: =CORREL(Panel!$T$2:$T$64,Panel!$R$2:$R$64) -> 0.16550781 | G28: =CORREL(Panel!$T$2:$T$64,Panel!$S$2:$S$64) -> -0.1632458 | H28: =CORREL(Panel!$T$2:$T$64,Panel!$K$2:$K$64) -> -0.49373224 | I28: =CORREL(Panel!$T$2:$T$64,Panel!$Q$2:$Q$64) -> -0.27830573 | J28: =CORREL(Panel!$T$2:$T$64,Panel!$M$2:$M$64) -> -0.23273743 | K28: =CORREL(Panel!$T$2:$T$64,Panel!$E$2:$E$64) -> 0.091410862
